Workbook

Sheet 기안서
A4: 모터원 고양지점 SR 컬렉션판매 인센티브 지급
A6: 월 | B6: 담당자 | C6: 판매수량 | D6: 판매금액 | E6: 매출이익 | F6: 인센티브총액
A7: 1 | B7: 이 동 민 | C7: =매출!W73 -> 28 | D7: =매출!W75 -> 0 | E7: =매출!W83 -> 0 | F7: =매출!W89 -> 0
A8: 누계 | B8: 누계 | C8: =SUM(C7:C7) -> 28 | D8: =SUM(D7:D7) -> 0 | E8: =SUM(E7:E7) -> 0 | F8: =SUM(F7:F7) -> 0
C15: `

Sheet 매출
B6: 고양 A&C SHOP 매출 보고
B7: 2026 | D7: 1 | I7: 2 | N7: 3 | S7: 4 | X7: 5 | AC7: 6 | AH7: 7 | AM7: 8 | AR7: 9 | AW7: 10 | BB7: 11 | BG7: 12
B9: 날짜 | C9: C4 (C) | D9: Date | E9: 원가 | F9: 매출 | G9: 이익율 | H9: 소계 | I9: Date | J9: 원가 | K9: 매출 | L9: 이익율 | M9: 소계 | N9: Date | O9: 원가 | P9: 매출 | Q9: 이익율 | R9: 소계 | S9: Date | T9: 원가 | U9: 매출 | V9: 이익율 | W9: 소계 | X9: Date | Y9: 원가 | Z9: 매출 | AA9: 이익율 | AB9: 소계 | AC9: Date | AD9: 원가 | AE9: 매출 | AF9: 이익율 | AG9: 소계 | AH9: Date | AI9: 원가 | AJ9: 매출 | AK9: 이익율 | AL9: 소계 | AM9: Date | AN9: 원가 | AO9: 매출 | AP9: 이익율 | AQ9: 소계 | AR9: Date | AS9: 원가 | AT9: 매출 | AU9: 이익율 | AV9: 소계 | AW9: Date | AX9: 원가 | AY9: 매출 | AZ9: 이익율 | BA9: 소계 | BB9: Date | BC9: 원가 | BD9: 매출 | BE9: 이익율 | BF9: 소계 | BG9: Date | BH9: 원가 | BI9: 매출 | BJ9: 이익율 | BK9: 소계 | BM9: 원가 | BN9: 매출 | BO9: 이익율 | BP9: 합계
C10: 쿠폰(L)
B11: 1 | C11: C | D11: =IFERROR(DATE($B$7,$D$7,B11),"") -> 46023 | E11: =SUMIFS('1월'!$N:$N,'1월'!$F:$F,"C0000004",'1월'!$I:$I,D11)+SUMIFS('1월'!$N:$N,'1월'!$F:$F,"C0000140",'1월'!$I:$I,D11,'1월'!$T:$T,"??C*")+SUMIFS('1월'!$N:$N,'1월'!$F:$F,"C0000140",'1월'!$I:$I,D11,'1월'!$T:$T,"??M*")+SUMIFS('1월'!$N:$N,'1월'!$F:$F,"C0000140",'1월'!$I:$I,D11,'1월'!$T:$T,"??Z*")+SUMIFS('1월'!$N:$N,'1월'!$F:$F,"C0000142",'1월'!$I:$I,D11) -> 0 | F11: =SUMIFS('1월'!$L:$L,'1월'!$F:$F,"C0000004",'1월'!$I:$I,D11)+SUMIFS('1월'!$L:$L,'1월'!$F:$F,"C0000140",'1월'!$I:$I,D11,'1월'!$T:$T,"??C*")+SUMIFS('1월'!$L:$L,'1월'!$F:$F,"C0000140",'1월'!$I:$I,D11,'1월'!$T:$T,"??M*")+SUMIFS('1월'!$L:$L,'1월'!$F:$F,"C0000140",'1월'!$I:$I,D11,'1월'!$T:$T,"??Z*")+SUMIFS('1월'!$L:$L,'1월'!$F:$F,"C0000142",'1월'!$I:$I,D11) -> 0 | G11: =IFERROR((F11/E11)-1,"") | H11: =F11+F12 -> 0 | I11: =IFERROR(DATE($B$7,I$7,$B11),"") -> 46054 | J11: =SUMIFS('2월'!$N:$N,'2월'!$F:$F,"C0000004",'2월'!$I:$I,I11)+SUMIFS('2월'!$N:$N,'2월'!$F:$F,"C0000140",'2월'!$I:$I,I11,'2월'!$T:$T,"??C*")+SUMIFS('2월'!$N:$N,'2월'!$F:$F,"C0000140",'2월'!$I:$I,I11,'2월'!$T:$T,"??M*")+SUMIFS('2월'!$N:$N,'2월'!$F:$F,"C0000140",'2월'!$I:$I,I11,'2월'!$T:$T,"??Z*")+SUMIFS('2월'!$N:$N,'2월'!$F:$F,"C0000142",'2월'!$I:$I,I11) -> 0 | K11: =SUMIFS('2월'!$L:$L,'2월'!$F:$F,"C0000004",'2월'!$I:$I,I11)+SUMIFS('2월'!$L:$L,'2월'!$F:$F,"C0000140",'2월'!$I:$I,I11,'2월'!$T:$T,"??C*")+SUMIFS('2월'!$L:$L,'2월'!$F:$F,"C0000140",'2월'!$I:$I,I11,'2월'!$T:$T,"??M*")+SUMIFS('2월'!$L:$L,'2월'!$F:$F,"C0000140",'2월'!$I:$I,I11,'2월'!$T:$T,"??Z*")+SUMIFS('2월'!$L:$L,'2월'!$F:$F,"C0000142",'2월'!$I:$I,I11) -> 0 | L11: =IFERROR((K11/J11)-1,"") | M11: =K11+K12 -> 0 | N11: =IFERROR(DATE($B$7,N$7,$B11),"") -> 46082 | O11: =SUMIFS('3월'!$N:$N,'3월'!$F:$F,"C0000004",'3월'!$I:$I,N11)+SUMIFS('3월'!$N:$N,'3월'!$F:$F,"C0000140",'3월'!$I:$I,N11,'3월'!$T:$T,"??C*")+SUMIFS('3월'!$N:$N,'3월'!$F:$F,"C0000140",'3월'!$I:$I,N11,'3월'!$T:$T,"??M*")+SUMIFS('3월'!$N:$N,'3월'!$F:$F,"C0000140",'3월'!$I:$I,N11,'3월'!$T:$T,"??Z*")+SUMIFS('3월'!$N:$N,'3월'!$F:$F,"C0000142",'3월'!$I:$I,N11) -> 0 | P11: =SUMIFS('3월'!$L:$L,'3월'!$F:$F,"C0000004",'3월'!$I:$I,N11)+SUMIFS('3월'!$L:$L,'3월'!$F:$F,"C0000140",'3월'!$I:$I,N11,'3월'!$T:$T,"??C*")+SUMIFS('3월'!$L:$L,'3월'!$F:$F,"C0000140",'3월'!$I:$I,N11,'3월'!$T:$T,"??M*")+SUMIFS('3월'!$L:$L,'3월'!$F:$F,"C0000140",'3월'!$I:$I,N11,'3월'!$T:$T,"??Z*")+SUMIFS('3월'!$L:$L,'3월'!$F:$F,"C0000142",'3월'!$I:$I,N11) -> 0 | Q11: =IFERROR((P11/O11)-1,"") | R11: =P11+P12 -> 0 | S11: =IFERROR(DATE($B$7,S$7,$B11),"") -> 46113 | T11: =SUMIFS('4월'!$N:$N,'4월'!$F:$F,"C0000004",'4월'!$I:$I,S11)+SUMIFS('4월'!$N:$N,'4월'!$F:$F,"C0000140",'4월'!$I:$I,S11,'4월'!$T:$T,"??C*")+SUMIFS('4월'!$N:$N,'4월'!$F:$F,"C0000140",'4월'!$I:$I,S11,'4월'!$T:$T,"??M*")+SUMIFS('4월'!$N:$N,'4월'!$F:$F,"C0000140",'4월'!$I:$I,S11,'4월'!$T:$T,"??Z*")+SUMIFS('4월'!$N:$N,'4월'!$F:$F,"C0000142",'4월'!$I:$I,S11) -> 0 | U11: =SUMIFS('4월'!$L:$L,'4월'!$F:$F,"C0000004",'4월'!$I:$I,S11)+SUMIFS('4월'!$L:$L,'4월'!$F:$F,"C0000140",'4월'!$I:$I,S11,'4월'!$T:$T,"??C*")+SUMIFS('4월'!$L:$L,'4월'!$F:$F,"C0000140",'4월'!$I:$I,S11,'4월'!$T:$T,"??M*")+SUMIFS('4월'!$L:$L,'4월'!$F:$F,"C0000140",'4월'!$I:$I,S11,'4월'!$T:$T,"??Z*")+SUMIFS('4월'!$L:$L,'4월'!$F:$F,"C0000142",'4월'!$I:$I,S11) -> 0 | V11: =IFERROR((U11/T11)-1,"") | W11: =U11+U12 -> 0 | X11: =IFERROR(DATE($B$7,X$7,$B11),"") -> 46143 | Y11: =SUMIFS('5월'!$N:$N,'5월'!$F:$F,"C0000004",'5월'!$I:$I,X11)+SUMIFS('5월'!$N:$N,'5월'!$F:$F,"C0000140",'5월'!$I:$I,X11,'5월'!$T:$T,"??C*")+SUMIFS('5월'!$N:$N,'5월'!$F:$F,"C0000140",'5월'!$I:$I,X11,'5월'!$T:$T,"??M*")+SUMIFS('5월'!$N:$N,'5월'!$F:$F,"C0000140",'5월'!$I:$I,X11,'5월'!$T:$T,"??Z*")+SUMIFS('5월'!$N:$N,'5월'!$F:$F,"C0000142",'5월'!$I:$I,X11) -> 0 | Z11: =SUMIFS('5월'!$L:$L,'5월'!$F:$F,"C0000004",'5월'!$I:$I,X11)+SUMIFS('5월'!$L:$L,'5월'!$F:$F,"C0000140",'5월'!$I:$I,X11,'5월'!$T:$T,"??C*")+SUMIFS('5월'!$L:$L,'5월'!$F:$F,"C0000140",'5월'!$I:$I,X11,'5월'!$T:$T,"??M*")+SUMIFS('5월'!$L:$L,'5월'!$F:$F,"C0000140",'5월'!$I:$I,X11,'5월'!$T:$T,"??Z*")+SUMIFS('5월'!$L:$L,'5월'!$F:$F,"C0000142",'5월'!$I:$I,X11) -> 0 | AA11: =IFERROR((Z11/Y11)-1,"") | AB11: =Z11+Z12 -> 0 | AC11: =IFERROR(DATE($B$7,AC$7,$B11),"") -> 46174 | AD11: =SUMIFS('6월'!$N:$N,'6월'!$F:$F,"C0000004",'6월'!$I:$I,AC11)+SUMIFS('6월'!$N:$N,'6월'!$F:$F,"C0000140",'6월'!$I:$I,AC11,'6월'!$T:$T,"??C*")+SUMIFS('6월'!$N:$N,'6월'!$F:$F,"C0000140",'6월'!$I:$I,AC11,'6월'!$T:$T,"??M*")+SUMIFS('6월'!$N:$N,'6월'!$F:$F,"C0000140",'6월'!$I:$I,AC11,'6월'!$T:$T,"??Z*")+SUMIFS('6월'!$N:$N,'6월'!$F:$F,"C0000142",'6월'!$I:$I,AC11) -> 0 | AE11: =SUMIFS('6월'!$L:$L,'6월'!$F:$F,"C0000004",'6월'!$I:$I,AC11)+SUMIFS('6월'!$L:$L,'6월'!$F:$F,"C0000140",'6월'!$I:$I,AC11,'6월'!$T:$T,"??C*")+SUMIFS('6월'!$L:$L,'6월'!$F:$F,"C0000140",'6월'!$I:$I,AC11,'6월'!$T:$T,"??M*")+SUMIFS('6월'!$L:$L,'6월'!$F:$F,"C0000140",'6월'!$I:$I,AC11,'6월'!$T:$T,"??Z*")+SUMIFS('6월'!$L:$L,'6월'!$F:$F,"C0000142",'6월'!$I:$I,AC11) -> 0 | AF11: =IFERROR((AE11/AD11)-1,"") | AG11: =AE11+AE12 -> 0 | AH11: =IFERROR(DATE($B$7,AH$7,$B11),"") -> 46204 | AI11: =SUMIFS('7월'!$N:$N,'7월'!$F:$F,"C0000004",'7월'!$I:$I,AH11)+SUMIFS('7월'!$N:$N,'7월'!$F:$F,"C0000140",'7월'!$I:$I,AH11,'7월'!$T:$T,"??C*")+SUMIFS('7월'!$N:$N,'7월'!$F:$F,"C0000140",'7월'!$I:$I,AH11,'7월'!$T:$T,"??M*")+SUMIFS('7월'!$N:$N,'7월'!$F:$F,"C0000140",'7월'!$I:$I,AH11,'7월'!$T:$T,"??Z*")+SUMIFS('7월'!$N:$N,'7월'!$F:$F,"C0000142",'7월'!$I:$I,AH11) -> 0 | AJ11: =SUMIFS('7월'!$L:$L,'7월'!$F:$F,"C0000004",'7월'!$I:$I,AH11)+SUMIFS('7월'!$L:$L,'7월'!$F:$F,"C0000140",'7월'!$I:$I,AH11,'7월'!$T:$T,"??C*")+SUMIFS('7월'!$L:$L,'7월'!$F:$F,"C0000140",'7월'!$I:$I,AH11,'7월'!$T:$T,"??M*")+SUMIFS('7월'!$L:$L,'7월'!$F:$F,"C0000140",'7월'!$I:$I,AH11,'7월'!$T:$T,"??Z*")+SUMIFS('7월'!$L:$L,'7월'!$F:$F,"C0000142",'7월'!$I:$I,AH11) -> 0 | AK11: =IFERROR((AJ11/AI11)-1,"") | AL11: =AJ11+AJ12 -> 0 | AM11: =IFERROR(DATE($B$7,AM$7,$B11),"") -> 46235 | AN11: =SUMIFS('8월'!$N:$N,'8월'!$F:$F,"C0000004",'8월'!$I:$I,AM11)+SUMIFS('8월'!$N:$N,'8월'!$F:$F,"C0000140",'8월'!$I:$I,AM11,'8월'!$T:$T,"??C*")+SUMIFS('8월'!$N:$N,'8월'!$F:$F,"C0000140",'8월'!$I:$I,AM11,'8월'!$T:$T,"??M*")+SUMIFS('8월'!$N:$N,'8월'!$F:$F,"C0000140",'8월'!$I:$I,AM11,'8월'!$T:$T,"??Z*")+SUMIFS('8월'!$N:$N,'8월'!$F:$F,"C0000142",'8월'!$I:$I,AM11) -> 0 | AO11: =SUMIFS('8월'!$L:$L,'8월'!$F:$F,"C0000004",'8월'!$I:$I,AM11)+SUMIFS('8월'!$L:$L,'8월'!$F:$F,"C0000140",'8월'!$I:$I,AM11,'8월'!$T:$T,"??C*")+SUMIFS('8월'!$L:$L,'8월'!$F:$F,"C0000140",'8월'!$I:$I,AM11,'8월'!$T:$T,"??M*")+SUMIFS('8월'!$L:$L,'8월'!$F:$F,"C0000140",'8월'!$I:$I,AM11,'8월'!$T:$T,"??Z*")+SUMIFS('8월'!$L:$L,'8월'!$F:$F,"C0000142",'8월'!$I:$I,AM11) -> 0 | AP11: =IFERROR((AO11/AN11)-1,"") | AQ11: =AO11+AO12 -> 0 | AR11: =IFERROR(DATE($B$7,AR$7,$B11),"") -> 46266 | AS11: =SUMIFS('9월'!$N:$N,'9월'!$F:$F,"C0000004",'9월'!$I:$I,AR11)+SUMIFS('9월'!$N:$N,'9월'!$F:$F,"C0000140",'9월'!$I:$I,AR11,'9월'!$T:$T,"??C*")+SUMIFS('9월'!$N:$N,'9월'!$F:$F,"C0000140",'9월'!$I:$I,AR11,'9월'!$T:$T,"??M*")+SUMIFS('9월'!$N:$N,'9월'!$F:$F,"C0000140",'9월'!$I:$I,AR11,'9월'!$T:$T,"??Z*")+SUMIFS('9월'!$N:$N,'9월'!$F:$F,"C0000142",'9월'!$I:$I,AR11) -> 1895.4136 | AT11: =SUMIFS('9월'!$L:$L,'9월'!$F:$F,"C0000004",'9월'!$I:$I,AR11)+SUMIFS('9월'!$L:$L,'9월'!$F:$F,"C0000140",'9월'!$I:$I,AR11,'9월'!$T:$T,"??C*")+SUMIFS('9월'!$L:$L,'9월'!$F:$F,"C0000140",'9월'!$I:$I,AR11,'9월'!$T:$T,"??M*")+SUMIFS('9월'!$L:$L,'9월'!$F:$F,"C0000140",'9월'!$I:$I,AR11,'9월'!$T:$T,"??Z*")+SUMIFS('9월'!$L:$L,'9월'!$F:$F,"C0000142",'9월'!$I:$I,AR11) -> 5500 | AU11: =IFERROR((AT11/AS11)-1,"") -> 1.9017413 | AV11: =AT11+AT12 -> 5500 | AW11: =IFERROR(DATE($B$7,AW$7,$B11),"") -> 46296 | AX11: =SUMIFS('10월'!$N:$N,'10월'!$F:$F,"C0000004",'10월'!$I:$I,AW11)+SUMIFS('10월'!$N:$N,'10월'!$F:$F,"C0000140",'10월'!$I:$I,AW11,'10월'!$T:$T,"??C*")+SUMIFS('10월'!$N:$N,'10월'!$F:$F,"C0000140",'10월'!$I:$I,AW11,'10월'!$T:$T,"??M*")+SUMIFS('10월'!$N:$N,'10월'!$F:$F,"C0000140",'10월'!$I:$I,AW11,'10월'!$T:$T,"??Z*")+SUMIFS('10월'!$N:$N,'10월'!$F:$F,"C0000142",'10월'!$I:$I,AW11) -> 0 | AY11: =SUMIFS('10월'!$L:$L,'10월'!$F:$F,"C0000004",'10월'!$I:$I,AW11)+SUMIFS('10월'!$L:$L,'10월'!$F:$F,"C0000140",'10월'!$I:$I,AW11,'10월'!$T:$T,"??C*")+SUMIFS('10월'!$L:$L,'10월'!$F:$F,"C0000140",'10월'!$I:$I,AW11,'10월'!$T:$T,"??M*")+SUMIFS('10월'!$L:$L,'10월'!$F:$F,"C0000140",'10월'!$I:$I,AW11,'10월'!$T:$T,"??Z*")+SUMIFS('10월'!$L:$L,'10월'!$F:$F,"C0000142",'10월'!$I:$I,AW11) -> 0 | AZ11: =IFERROR((AY11/AX11)-1,"") | BA11: =AY11+AY12 -> 0 | BB11: =IFERROR(DATE($B$7,BB$7,$B11),"") -> 46327 | BC11: =SUMIFS('11월'!$N:$N,'11월'!$F:$F,"C0000004",'11월'!$I:$I,BB11)+SUMIFS('11월'!$N:$N,'11월'!$F:$F,"C0000140",'11월'!$I:$I,BB11,'11월'!$T:$T,"??C*")+SUMIFS('11월'!$N:$N,'11월'!$F:$F,"C0000140",'11월'!$I:$I,BB11,'11월'!$T:$T,"??M*")+SUMIFS('11월'!$N:$N,'11월'!$F:$F,"C0000140",'11월'!$I:$I,BB11,'11월'!$T:$T,"??Z*")+SUMIFS('11월'!$N:$N,'11월'!$F:$F,"C0000142",'11월'!$I:$I,BB11) -> 0 | BD11: =SUMIFS('11월'!$L:$L,'11월'!$F:$F,"C0000004",'11월'!$I:$I,BB11)+SUMIFS('11월'!$L:$L,'11월'!$F:$F,"C0000140",'11월'!$I:$I,BB11,'11월'!$T:$T,"??C*")+SUMIFS('11월'!$L:$L,'11월'!$F:$F,"C0000140",'11월'!$I:$I,BB11,'11월'!$T:$T,"??M*")+SUMIFS('11월'!$L:$L,'11월'!$F:$F,"C0000140",'11월'!$I:$I,BB11,'11월'!$T:$T,"??Z*")+SUMIFS('11월'!$L:$L,'11월'!$F:$F,"C0000142",'11월'!$I:$I,BB11) -> 0 | BE11: =IFERROR((BD11/BC11)-1,"") | BF11: =BD11+BD12 -> 0 | BG11: =IFERROR(DATE($B$7,BG$7,$B11),"") -> 46357 | BH11: =SUMIFS('12월'!$N:$N,'12월'!$F:$F,"C0000004",'12월'!$I:$I,BG11)+SUMIFS('12월'!$N:$N,'12월'!$F:$F,"C0000140",'12월'!$I:$I,BG11,'12월'!$T:$T,"??C*")+SUMIFS('12월'!$N:$N,'12월'!$F:$F,"C0000140",'12월'!$I:$I,BG11,'12월'!$T:$T,"??M*")+SUMIFS('12월'!$N:$N,'12월'!$F:$F,"C0000140",'12월'!$I:$I,BG11,'12월'!$T:$T,"??Z*")+SUMIFS('12월'!$N:$N,'12월'!$F:$F,"C0000142",'12월'!$I:$I,BG11) -> 0 | BI11: =SUMIFS('12월'!$L:$L,'12월'!$F:$F,"C0000004",'12월'!$I:$I,BG11)+SUMIFS('12월'!$L:$L,'12월'!$F:$F,"C0000140",'12월'!$I:$I,BG11,'12월'!$T:$T,"??C*")+SUMIFS('12월'!$L:$L,'12월'!$F:$F,"C0000140",'12월'!$I:$I,BG11,'12월'!$T:$T,"??M*")+SUMIFS('12월'!$L:$L,'12월'!$F:$F,"C0000140",'12월'!$I:$I,BG11,'12월'!$T:$T,"??Z*")+SUMIFS('12월'!$L:$L,'12월'!$F:$F,"C0000142",'12월'!$I:$I,BG11) -> 0 | BJ11: =IFERROR((BI11/BH11)-1,"") | BK11: =BI11+BI12 -> 0
C12: L | E12: =SUMIFS('1월'!$N:$N,'1월'!$F:$F,"*L*",'1월'!$I:$I,D11,'1월'!$S:$S,"윤준희") -> 0 | F12: =SUMIFS('1월'!$L:$L,'1월'!$F:$F,"*L*",'1월'!$I:$I,D11,'1월'!$S:$S,"윤준희") -> 0 | G12: =IFERROR((F12/E12)-1,"") | J12: =SUMIFS('2월'!$N:$N,'2월'!$F:$F,"*L*",'2월'!$I:$I,I11,'2월'!$S:$S,"윤준희") -> 0 | K12: =SUMIFS('2월'!$L:$L,'2월'!$F:$F,"*L*",'2월'!$I:$I,I11,'2월'!$S:$S,"윤준희") -> 0 | L12: =IFERROR((K12/J12)-1,"") | O12: =SUMIFS('3월'!$N:$N,'3월'!$F:$F,"*L*",'3월'!$I:$I,N11,'3월'!$S:$S,"윤준희") -> 0 | P12: =SUMIFS('3월'!$L:$L,'3월'!$F:$F,"*L*",'3월'!$I:$I,N11,'3월'!$S:$S,"윤준희") -> 0 | Q12: =IFERROR((P12/O12)-1,"") | T12: =SUMIFS('4월'!$N:$N,'4월'!$F:$F,"*L*",'4월'!$I:$I,S11,'4월'!$S:$S,"윤준희") -> 0 | U12: =SUMIFS('4월'!$L:$L,'4월'!$F:$F,"*L*",'4월'!$I:$I,S11,'4월'!$S:$S,"윤준희") -> 0 | V12: =IFERROR((U12/T12)-1,"") | Y12: =SUMIFS('5월'!$N:$N,'5월'!$F:$F,"*L*",'5월'!$I:$I,X11,'5월'!$S:$S,"윤준희") -> 0 | Z12: =SUMIFS('5월'!$L:$L,'5월'!$F:$F,"*L*",'5월'!$I:$I,X11,'5월'!$S:$S,"윤준희") -> 0 | AA12: =IFERROR((Z12/Y12)-1,"") | AD12: =SUMIFS('6월'!$N:$N,'6월'!$F:$F,"*L*",'6월'!$I:$I,AC11,'6월'!$S:$S,"윤준희") -> 0 | AE12: =SUMIFS('6월'!$L:$L,'6월'!$F:$F,"*L*",'6월'!$I:$I,AC11,'6월'!$S:$S,"윤준희")+SUMIFS('6월'!$L:$L,'6월'!$F:$F,"*L*",'6월'!$I:$I,AC11,'6월'!$S:$S,"윤준희") -> 0 | AF12: =IFERROR((AE12/AD12)-1,"") | AI12: =SUMIFS('7월'!$N:$N,'7월'!$F:$F,"*L*",'7월'!$I:$I,AH11,'7월'!$S:$S,"윤준희") -> 0 | AJ12: =SUMIFS('7월'!$L:$L,'7월'!$F:$F,"*L*",'7월'!$I:$I,AH11,'7월'!$S:$S,"윤준희") -> 0 | AK12: =IFERROR((AJ12/AI12)-1,"") | AN12: =SUMIFS('8월'!$N:$N,'8월'!$F:$F,"*L*",'8월'!$I:$I,AM11,'8월'!$S:$S,"윤준희") -> 0 | AO12: =SUMIFS('8월'!$L:$L,'8월'!$F:$F,"*L*",'8월'!$I:$I,AM11,'8월'!$S:$S,"윤준희") -> 0 | AP12: =IFERROR((AO12/AN12)-1,"") | AS12: =SUMIFS('9월'!$N:$N,'9월'!$F:$F,"*L*",'9월'!$I:$I,AR11,'9월'!$S:$S,"윤준희") -> 0 | AT12: =SUMIFS('9월'!$L:$L,'9월'!$F:$F,"*L*",'9월'!$I:$I,AR11,'9월'!$S:$S,"윤준희") -> 0 | AU12: =IFERROR((AT12/AS12)-1,"") | AX12: =SUMIFS('10월'!$N:$N,'10월'!$F:$F,"*L*",'10월'!$I:$I,AW11,'10월'!$S:$S,"윤준희") -> 0 | AY12: =SUMIFS('10월'!$L:$L,'10월'!$F:$F,"*L*",'10월'!$I:$I,AW11,'10월'!$S:$S,"윤준희") -> 0 | AZ12: =IFERROR((AY12/AX12)-1,"") | BC12: =SUMIFS('11월'!$N:$N,'11월'!$F:$F,"*L*",'11월'!$I:$I,BB11,'11월'!$S:$S,"윤준희") -> 0 | BD12: =SUMIFS('11월'!$L:$L,'11월'!$F:$F,"*L*",'11월'!$I:$I,BB11,'11월'!$S:$S,"윤준희") -> 0 | BE12: =IFERROR((BD12/BC12)-1,"") | BH12: =SUMIFS('12월'!$N:$N,'12월'!$F:$F,"*L*",'12월'!$I:$I,BG11,'12월'!$S:$S,"윤준희") -> 0 | BI12: =SUMIFS('12월'!$L:$L,'12월'!$F:$F,"*L*",'12월'!$I:$I,BG11,'12월'!$S:$S,"윤준희") -> 0 | BJ12: =IFERROR((BI12/BH12)-1,"")
B13: 2 | C13: C | D13: =IFERROR(DATE($B$7,$D$7,B13),"") -> 46024 | E13: =SUMIFS('1월'!$N:$N,'1월'!$F:$F,"C0000004",'1월'!$I:$I,D13)+SUMIFS('1월'!$N:$N,'1월'!$F:$F,"C0000140",'1월'!$I:$I,D13,'1월'!$T:$T,"??C*")+SUMIFS('1월'!$N:$N,'1월'!$F:$F,"C0000140",'1월'!$I:$I,D13,'1월'!$T:$T,"??M*")+SUMIFS('1월'!$N:$N,'1월'!$F:$F,"C0000140",'1월'!$I:$I,D13,'1월'!$T:$T,"??Z*")+SUMIFS('1월'!$N:$N,'1월'!$F:$F,"C0000142",'1월'!$I:$I,D13) -> 0 | F13: =SUMIFS('1월'!$L:$L,'1월'!$F:$F,"C0000004",'1월'!$I:$I,D13)+SUMIFS('1월'!$L:$L,'1월'!$F:$F,"C0000140",'1월'!$I:$I,D13,'1월'!$T:$T,"??C*")+SUMIFS('1월'!$L:$L,'1월'!$F:$F,"C0000140",'1월'!$I:$I,D13,'1월'!$T:$T,"??M*")+SUMIFS('1월'!$L:$L,'1월'!$F:$F,"C0000140",'1월'!$I:$I,D13,'1월'!$T:$T,"??Z*")+SUMIFS('1월'!$L:$L,'1월'!$F:$F,"C0000142",'1월'!$I:$I,D13) -> 0 | G13: =IFERROR((F13/E13)-1,"") | H13: =F13+F14 -> 0 | I13: =IFERROR(DATE($B$7,I$7,$B13),"") -> 46055 | J13: =SUMIFS('2월'!$N:$N,'2월'!$F:$F,"C0000004",'2월'!$I:$I,I13)+SUMIFS('2월'!$N:$N,'2월'!$F:$F,"C0000140",'2월'!$I:$I,I13,'2월'!$T:$T,"??C*")+SUMIFS('2월'!$N:$N,'2월'!$F:$F,"C0000140",'2월'!$I:$I,I13,'2월'!$T:$T,"??M*")+SUMIFS('2월'!$N:$N,'2월'!$F:$F,"C0000140",'2월'!$I:$I,I13,'2월'!$T:$T,"??Z*")+SUMIFS('2월'!$N:$N,'2월'!$F:$F,"C0000142",'2월'!$I:$I,I13) -> 0 | K13: =SUMIFS('2월'!$L:$L,'2월'!$F:$F,"C0000004",'2월'!$I:$I,I13)+SUMIFS('2월'!$L:$L,'2월'!$F:$F,"C0000140",'2월'!$I:$I,I13,'2월'!$T:$T,"??C*")+SUMIFS('2월'!$L:$L,'2월'!$F:$F,"C0000140",'2월'!$I:$I,I13,'2월'!$T:$T,"??M*")+SUMIFS('2월'!$L:$L,'2월'!$F:$F,"C0000140",'2월'!$I:$I,I13,'2월'!$T:$T,"??Z*")+SUMIFS('2월'!$L:$L,'2월'!$F:$F,"C0000142",'2월'!$I:$I,I13) -> 0 | L13: =IFERROR((K13/J13)-1,"") | M13: =K13+K14 -> 0 | N13: =IFERROR(DATE($B$7,N$7,$B13),"") -> 46083 | O13: =SUMIFS('3월'!$N:$N,'3월'!$F:$F,"C0000004",'3월'!$I:$I,N13)+SUMIFS('3월'!$N:$N,'3월'!$F:$F,"C0000140",'3월'!$I:$I,N13,'3월'!$T:$T,"??C*")+SUMIFS('3월'!$N:$N,'3월'!$F:$F,"C0000140",'3월'!$I:$I,N13,'3월'!$T:$T,"??M*")+SUMIFS('3월'!$N:$N,'3월'!$F:$F,"C0000140",'3월'!$I:$I,N13,'3월'!$T:$T,"??Z*")+SUMIFS('3월'!$N:$N,'3월'!$F:$F,"C0000142",'3월'!$I:$I,N13) -> 0 | P13: =SUMIFS('3월'!$L:$L,'3월'!$F:$F,"C0000004",'3월'!$I:$I,N13)+SUMIFS('3월'!$L:$L,'3월'!$F:$F,"C0000140",'3월'!$I:$I,N13,'3월'!$T:$T,"??C*")+SUMIFS('3월'!$L:$L,'3월'!$F:$F,"C0000140",'3월'!$I:$I,N13,'3월'!$T:$T,"??M*")+SUMIFS('3월'!$L:$L,'3월'!$F:$F,"C0000140",'3월'!$I:$I,N13,'3월'!$T:$T,"??Z*")+SUMIFS('3월'!$L:$L,'3월'!$F:$F,"C0000142",'3월'!$I:$I,N13) -> 0 | Q13: =IFERROR((P13/O13)-1,"") | R13: =P13+P14 -> 0 | S13: =IFERROR(DATE($B$7,S$7,$B13),"") -> 46114 | T13: =SUMIFS('4월'!$N:$N,'4월'!$F:$F,"C0000004",'4월'!$I:$I,S13)+SUMIFS('4월'!$N:$N,'4월'!$F:$F,"C0000140",'4월'!$I:$I,S13,'4월'!$T:$T,"??C*")+SUMIFS('4월'!$N:$N,'4월'!$F:$F,"C0000140",'4월'!$I:$I,S13,'4월'!$T:$T,"??M*")+SUMIFS('4월'!$N:$N,'4월'!$F:$F,"C0000140",'4월'!$I:$I,S13,'4월'!$T:$T,"??Z*")+SUMIFS('4월'!$N:$N,'4월'!$F:$F,"C0000142",'4월'!$I:$I,S13) -> 0 | U13: =SUMIFS('4월'!$L:$L,'4월'!$F:$F,"C0000004",'4월'!$I:$I,S13)+SUMIFS('4월'!$L:$L,'4월'!$F:$F,"C0000140",'4월'!$I:$I,S13,'4월'!$T:$T,"??C*")+SUMIFS('4월'!$L:$L,'4월'!$F:$F,"C0000140",'4월'!$I:$I,S13,'4월'!$T:$T,"??M*")+SUMIFS('4월'!$L:$L,'4월'!$F:$F,"C0000140",'4월'!$I:$I,S13,'4월'!$T:$T,"??Z*")+SUMIFS('4월'!$L:$L,'4월'!$F:$F,"C0000142",'4월'!$I:$I,S13) -> 0 | V13: =IFERROR((U13/T13)-1,"") | W13: =U13+U14 -> 0 | X13: =IFERROR(DATE($B$7,X$7,$B13),"") -> 46144 | Y13: =SUMIFS('5월'!$N:$N,'5월'!$F:$F,"C0000004",'5월'!$I:$I,X13)+SUMIFS('5월'!$N:$N,'5월'!$F:$F,"C0000140",'5월'!$I:$I,X13,'5월'!$T:$T,"??C*")+SUMIFS('5월'!$N:$N,'5월'!$F:$F,"C0000140",'5월'!$I:$I,X13,'5월'!$T:$T,"??M*")+SUMIFS('5월'!$N:$N,'5월'!$F:$F,"C0000140",'5월'!$I:$I,X13,'5월'!$T:$T,"??Z*")+SUMIFS('5월'!$N:$N,'5월'!$F:$F,"C0000142",'5월'!$I:$I,X13) -> 0 | Z13: =SUMIFS('5월'!$L:$L,'5월'!$F:$F,"C0000004",'5월'!$I:$I,X13)+SUMIFS('5월'!$L:$L,'5월'!$F:$F,"C0000140",'5월'!$I:$I,X13,'5월'!$T:$T,"??C*")+SUMIFS('5월'!$L:$L,'5월'!$F:$F,"C0000140",'5월'!$I:$I,X13,'5월'!$T:$T,"??M*")+SUMIFS('5월'!$L:$L,'5월'!$F:$F,"C0000140",'5월'!$I:$I,X13,'5월'!$T:$T,"??Z*")+SUMIFS('5월'!$L:$L,'5월'!$F:$F,"C0000142",'5월'!$I:$I,X13) -> 0 | AA13: =IFERROR((Z13/Y13)-1,"") | AB13: =Z13+Z14 -> 0 | AC13: =IFERROR(DATE($B$7,AC$7,$B13),"") -> 46175 | AD13: =SUMIFS('6월'!$N:$N,'6월'!$F:$F,"C0000004",'6월'!$I:$I,AC13)+SUMIFS('6월'!$N:$N,'6월'!$F:$F,"C0000140",'6월'!$I:$I,AC13,'6월'!$T:$T,"??C*")+SUMIFS('6월'!$N:$N,'6월'!$F:$F,"C0000140",'6월'!$I:$I,AC13,'6월'!$T:$T,"??M*")+SUMIFS('6월'!$N:$N,'6월'!$F:$F,"C0000140",'6월'!$I:$I,AC13,'6월'!$T:$T,"??Z*")+SUMIFS('6월'!$N:$N,'6월'!$F:$F,"C0000142",'6월'!$I:$I,AC13) -> 0 | AE13: =SUMIFS('6월'!$L:$L,'6월'!$F:$F,"C0000004",'6월'!$I:$I,AC13)+SUMIFS('6월'!$L:$L,'6월'!$F:$F,"C0000140",'6월'!$I:$I,AC13,'6월'!$T:$T,"??C*")+SUMIFS('6월'!$L:$L,'6월'!$F:$F,"C0000140",'6월'!$I:$I,AC13,'6월'!$T:$T,"??M*")+SUMIFS('6월'!$L:$L,'6월'!$F:$F,"C0000140",'6월'!$I:$I,AC13,'6월'!$T:$T,"??Z*")+SUMIFS('6월'!$L:$L,'6월'!$F:$F,"C0000142",'6월'!$I:$I,AC13) -> 0 | AF13: =IFERROR((AE13/AD13)-1,"") | AG13: =AE13+AE14 -> 0 | AH13: =IFERROR(DATE($B$7,AH$7,$B13),"") -> 46205 | AI13: =SUMIFS('7월'!$N:$N,'7월'!$F:$F,"C0000004",'7월'!$I:$I,AH13)+SUMIFS('7월'!$N:$N,'7월'!$F:$F,"C0000140",'7월'!$I:$I,AH13,'7월'!$T:$T,"??C*")+SUMIFS('7월'!$N:$N,'7월'!$F:$F,"C0000140",'7월'!$I:$I,AH13,'7월'!$T:$T,"??M*")+SUMIFS('7월'!$N:$N,'7월'!$F:$F,"C0000140",'7월'!$I:$I,AH13,'7월'!$T:$T,"??Z*")+SUMIFS('7월'!$N:$N,'7월'!$F:$F,"C0000142",'7월'!$I:$I,AH13) -> 0 | AJ13: =SUMIFS('7월'!$L:$L,'7월'!$F:$F,"C0000004",'7월'!$I:$I,AH13)+SUMIFS('7월'!$L:$L,'7월'!$F:$F,"C0000140",'7월'!$I:$I,AH13,'7월'!$T:$T,"??C*")+SUMIFS('7월'!$L:$L,'7월'!$F:$F,"C0000140",'7월'!$I:$I,AH13,'7월'!$T:$T,"??M*")+SUMIFS('7월'!$L:$L,'7월'!$F:$F,"C0000140",'7월'!$I:$I,AH13,'7월'!$T:$T,"??Z*")+SUMIFS('7월'!$L:$L,'7월'!$F:$F,"C0000142",'7월'!$I:$I,AH13) -> 0 | AK13: =IFERROR((AJ13/AI13)-1,"") | AL13: =AJ13+AJ14 -> 0 | AM13: =IFERROR(DATE($B$7,AM$7,$B13),"") -> 46236 | AN13: =SUMIFS('8월'!$N:$N,'8월'!$F:$F,"C0000004",'8월'!$I:$I,AM13)+SUMIFS('8월'!$N:$N,'8월'!$F:$F,"C0000140",'8월'!$I:$I,AM13,'8월'!$T:$T,"??C*")+SUMIFS('8월'!$N:$N,'8월'!$F:$F,"C0000140",'8월'!$I:$I,AM13,'8월'!$T:$T,"??M*")+SUMIFS('8월'!$N:$N,'8월'!$F:$F,"C0000140",'8월'!$I:$I,AM13,'8월'!$T:$T,"??Z*")+SUMIFS('8월'!$N:$N,'8월'!$F:$F,"C0000142",'8월'!$I:$I,AM13) -> 0 | AO13: =SUMIFS('8월'!$L:$L,'8월'!$F:$F,"C0000004",'8월'!$I:$I,AM13)+SUMIFS('8월'!$L:$L,'8월'!$F:$F,"C0000140",'8월'!$I:$I,AM13,'8월'!$T:$T,"??C*")+SUMIFS('8월'!$L:$L,'8월'!$F:$F,"C0000140",'8월'!$I:$I,AM13,'8월'!$T:$T,"??M*")+SUMIFS('8월'!$L:$L,'8월'!$F:$F,"C0000140",'8월'!$I:$I,AM13,'8월'!$T:$T,"??Z*")+SUMIFS('8월'!$L:$L,'8월'!$F:$F,"C0000142",'8월'!$I:$I,AM13) -> 0 | AP13: =IFERROR((AO13/AN13)-1,"") | AQ13: =AO13+AO14 -> 0 | AR13: =IFERROR(DATE($B$7,AR$7,$B13),"") -> 46267 | AS13: =SUMIFS('9월'!$N:$N,'9월'!$F:$F,"C0000004",'9월'!$I:$I,AR13)+SUMIFS('9월'!$N:$N,'9월'!$F:$F,"C0000140",'9월'!$I:$I,AR13,'9월'!$T:$T,"??C*")+SUMIFS('9월'!$N:$N,'9월'!$F:$F,"C0000140",'9월'!$I:$I,AR13,'9월'!$T:$T,"??M*")+SUMIFS('9월'!$N:$N,'9월'!$F:$F,"C0000140",'9월'!$I:$I,AR13,'9월'!$T:$T,"??Z*")+SUMIFS('9월'!$N:$N,'9월'!$F:$F,"C0000142",'9월'!$I:$I,AR13) -> 54459.406 | AT13: =SUMIFS('9월'!$L:$L,'9월'!$F:$F,"C0000004",'9월'!$I:$I,AR13)+SUMIFS('9월'!$L:$L,'9월'!$F:$F,"C0000140",'9월'!$I:$I,AR13,'9월'!$T:$T,"??C*")+SUMIFS('9월'!$L:$L,'9월'!$F:$F,"C0000140",'9월'!$I:$I,AR13,'9월'!$T:$T,"??M*")+SUMIFS('9월'!$L:$L,'9월'!$F:$F,"C0000140",'9월'!$I:$I,AR13,'9월'!$T:$T,"??Z*")+SUMIFS('9월'!$L:$L,'9월'!$F:$F,"C0000142",'9월'!$I:$I,AR13) -> 92000 | AU13: =IFERROR((AT13/AS13)-1,"") -> 0.68933167 | AV13: =AT13+AT14 -> 92000 | AW13: =IFERROR(DATE($B$7,AW$7,$B13),"") -> 46297 | AX13: =SUMIFS('10월'!$N:$N,'10월'!$F:$F,"C0000004",'10월'!$I:$I,AW13)+SUMIFS('10월'!$N:$N,'10월'!$F:$F,"C0000140",'10월'!$I:$I,AW13,'10월'!$T:$T,"??C*")+SUMIFS('10월'!$N:$N,'10월'!$F:$F,"C0000140",'10월'!$I:$I,AW13,'10월'!$T:$T,"??M*")+SUMIFS('10월'!$N:$N,'10월'!$F:$F,"C0000140",'10월'!$I:$I,AW13,'10월'!$T:$T,"??Z*")+SUMIFS('10월'!$N:$N,'10월'!$F:$F,"C0000142",'10월'!$I:$I,AW13) -> 0 | AY13: =SUMIFS('10월'!$L:$L,'10월'!$F:$F,"C0000004",'10월'!$I:$I,AW13)+SUMIFS('10월'!$L:$L,'10월'!$F:$F,"C0000140",'10월'!$I:$I,AW13,'10월'!$T:$T,"??C*")+SUMIFS('10월'!$L:$L,'10월'!$F:$F,"C0000140",'10월'!$I:$I,AW13,'10월'!$T:$T,"??M*")+SUMIFS('10월'!$L:$L,'10월'!$F:$F,"C0000140",'10월'!$I:$I,AW13,'10월'!$T:$T,"??Z*")+SUMIFS('10월'!$L:$L,'10월'!$F:$F,"C0000142",'10월'!$I:$I,AW13) -> 0 | AZ13: =IFERROR((AY13/AX13)-1,"") | BA13: =AY13+AY14 -> 0 | BB13: =IFERROR(DATE($B$7,BB$7,$B13),"") -> 46328 | BC13: =SUMIFS('11월'!$N:$N,'11월'!$F:$F,"C0000004",'11월'!$I:$I,BB13)+SUMIFS('11월'!$N:$N,'11월'!$F:$F,"C0000140",'11월'!$I:$I,BB13,'11월'!$T:$T,"??C*")+SUMIFS('11월'!$N:$N,'11월'!$F:$F,"C0000140",'11월'!$I:$I,BB13,'11월'!$T:$T,"??M*")+SUMIFS('11월'!$N:$N,'11월'!$F:$F,"C0000140",'11월'!$I:$I,BB13,'11월'!$T:$T,"??Z*")+SUMIFS('11월'!$N:$N,'11월'!$F:$F,"C0000142",'11월'!$I:$I,BB13) -> 0 | BD13: =SUMIFS('11월'!$L:$L,'11월'!$F:$F,"C0000004",'11월'!$I:$I,BB13)+SUMIFS('11월'!$L:$L,'11월'!$F:$F,"C0000140",'11월'!$I:$I,BB13,'11월'!$T:$T,"??C*")+SUMIFS('11월'!$L:$L,'11월'!$F:$F,"C0000140",'11월'!$I:$I,BB13,'11월'!$T:$T,"??M*")+SUMIFS('11월'!$L:$L,'11월'!$F:$F,"C0000140",'11월'!$I:$I,BB13,'11월'!$T:$T,"??Z*")+SUMIFS('11월'!$L:$L,'11월'!$F:$F,"C0000142",'11월'!$I:$I,BB13) -> 0 | BE13: =IFERROR((BD13/BC13)-1,"") | BF13: =BD13+BD14 -> 0 | BG13: =IFERROR(DATE($B$7,BG$7,$B13),"") -> 46358 | BH13: =SUMIFS('12월'!$N:$N,'12월'!$F:$F,"C0000004",'12월'!$I:$I,BG13)+SUMIFS('12월'!$N:$N,'12월'!$F:$F,"C0000140",'12월'!$I:$I,BG13,'12월'!$T:$T,"??C*")+SUMIFS('12월'!$N:$N,'12월'!$F:$F,"C0000140",'12월'!$I:$I,BG13,'12월'!$T:$T,"??M*")+SUMIFS('12월'!$N:$N,'12월'!$F:$F,"C0000140",'12월'!$I:$I,BG13,'12월'!$T:$T,"??Z*")+SUMIFS('12월'!$N:$N,'12월'!$F:$F,"C0000142",'12월'!$I:$I,BG13) -> 0 | BI13: =SUMIFS('12월'!$L:$L,'12월'!$F:$F,"C0000004",'12월'!$I:$I,BG13)+SUMIFS('12월'!$L:$L,'12월'!$F:$F,"C0000140",'12월'!$I:$I,BG13,'12월'!$T:$T,"??C*")+SUMIFS('12월'!$L:$L,'12월'!$F:$F,"C0000140",'12월'!$I:$I,BG13,'12월'!$T:$T,"??M*")+SUMIFS('12월'!$L:$L,'12월'!$F:$F,"C0000140",'12월'!$I:$I,BG13,'12월'!$T:$T,"??Z*")+SUMIFS('12월'!$L:$L,'12월'!$F:$F,"C0000142",'12월'!$I:$I,BG13) -> 0 | BJ13: =IFERROR((BI13/BH13)-1,"") | BK13: =BI13+BI14 -> 0
C14: L | E14: =SUMIFS('1월'!$N:$N,'1월'!$F:$F,"*L*",'1월'!$I:$I,D13,'1월'!$S:$S,"윤준희") -> 0 | F14: =SUMIFS('1월'!$L:$L,'1월'!$F:$F,"*L*",'1월'!$I:$I,D13,'1월'!$S:$S,"윤준희") -> 0 | G14: =IFERROR((F14/E14)-1,"") | J14: =SUMIFS('2월'!$N:$N,'2월'!$F:$F,"*L*",'2월'!$I:$I,I13,'2월'!$S:$S,"윤준희") -> 0 | K14: =SUMIFS('2월'!$L:$L,'2월'!$F:$F,"*L*",'2월'!$I:$I,I13,'2월'!$S:$S,"윤준희") -> 0 | L14: =IFERROR((K14/J14)-1,"") | O14: =SUMIFS('3월'!$N:$N,'3월'!$F:$F,"*L*",'3월'!$I:$I,N13,'3월'!$S:$S,"윤준희") -> 0 | P14: =SUMIFS('3월'!$L:$L,'3월'!$F:$F,"*L*",'3월'!$I:$I,N13,'3월'!$S:$S,"윤준희") -> 0 | Q14: =IFERROR((P14/O14)-1,"") | T14: =SUMIFS('4월'!$N:$N,'4월'!$F:$F,"*L*",'4월'!$I:$I,S13,'4월'!$S:$S,"윤준희") -> 0 | U14: =SUMIFS('4월'!$L:$L,'4월'!$F:$F,"*L*",'4월'!$I:$I,S13,'4월'!$S:$S,"윤준희") -> 0 | V14: =IFERROR((U14/T14)-1,"") | Y14: =SUMIFS('5월'!$N:$N,'5월'!$F:$F,"*L*",'5월'!$I:$I,X13,'5월'!$S:$S,"윤준희") -> 0 | Z14: =SUMIFS('5월'!$L:$L,'5월'!$F:$F,"*L*",'5월'!$I:$I,X13,'5월'!$S:$S,"윤준희") -> 0 | AA14: =IFERROR((Z14/Y14)-1,"") | AD14: =SUMIFS('6월'!$N:$N,'6월'!$F:$F,"*L*",'6월'!$I:$I,AC13,'6월'!$S:$S,"윤준희") -> 0 | AE14: =SUMIFS('6월'!$L:$L,'6월'!$F:$F,"*L*",'6월'!$I:$I,AC13,'6월'!$S:$S,"윤준희") -> 0 | AF14: =IFERROR((AE14/AD14)-1,"") | AI14: =SUMIFS('7월'!$N:$N,'7월'!$F:$F,"*L*",'7월'!$I:$I,AH13,'7월'!$S:$S,"윤준희") -> 0 | AJ14: =SUMIFS('7월'!$L:$L,'7월'!$F:$F,"*L*",'7월'!$I:$I,AH13,'7월'!$S:$S,"윤준희") -> 0 | AK14: =IFERROR((AJ14/AI14)-1,"") | AN14: =SUMIFS('8월'!$N:$N,'8월'!$F:$F,"*L*",'8월'!$I:$I,AM13,'8월'!$S:$S,"윤준희") -> 0 | AO14: =SUMIFS('8월'!$L:$L,'8월'!$F:$F,"*L*",'8월'!$I:$I,AM13,'8월'!$S:$S,"윤준희") -> 0 | AP14: =IFERROR((AO14/AN14)-1,"") | AS14: =SUMIFS('9월'!$N:$N,'9월'!$F:$F,"*L*",'9월'!$I:$I,AR13,'9월'!$S:$S,"윤준희") -> 0 | AT14: =SUMIFS('9월'!$L:$L,'9월'!$F:$F,"*L*",'9월'!$I:$I,AR13,'9월'!$S:$S,"윤준희") -> 0 | AU14: =IFERROR((AT14/AS14)-1,"") | AX14: =SUMIFS('10월'!$N:$N,'10월'!$F:$F,"*L*",'10월'!$I:$I,AW13,'10월'!$S:$S,"윤준희") -> 0 | AY14: =SUMIFS('10월'!$L:$L,'10월'!$F:$F,"*L*",'10월'!$I:$I,AW13,'10월'!$S:$S,"윤준희") -> 0 | AZ14: =IFERROR((AY14/AX14)-1,"") | BC14: =SUMIFS('11월'!$N:$N,'11월'!$F:$F,"*L*",'11월'!$I:$I,BB13,'11월'!$S:$S,"윤준희") -> 0 | BD14: =SUMIFS('11월'!$L:$L,'11월'!$F:$F,"*L*",'11월'!$I:$I,BB13,'11월'!$S:$S,"윤준희") -> 0 | BE14: =IFERROR((BD14/BC14)-1,"") | BH14: =SUMIFS('12월'!$N:$N,'12월'!$F:$F,"*L*",'12월'!$I:$I,BG13,'12월'!$S:$S,"윤준희") -> 0 | BI14: =SUMIFS('12월'!$L:$L,'12월'!$F:$F,"*L*",'12월'!$I:$I,BG13,'12월'!$S:$S,"윤준희") -> 0 | BJ14: =IFERROR((BI14/BH14)-1,"")
B15: 3 | C15: C | D15: =IFERROR(DATE($B$7,$D$7,B15),"") -> 46025 | E15: =SUMIFS('1월'!$N:$N,'1월'!$F:$F,"C0000004",'1월'!$I:$I,D15)+SUMIFS('1월'!$N:$N,'1월'!$F:$F,"C0000140",'1월'!$I:$I,D15,'1월'!$T:$T,"??C*")+SUMIFS('1월'!$N:$N,'1월'!$F:$F,"C0000140",'1월'!$I:$I,D15,'1월'!$T:$T,"??M*")+SUMIFS('1월'!$N:$N,'1월'!$F:$F,"C0000140",'1월'!$I:$I,D15,'1월'!$T:$T,"??Z*")+SUMIFS('1월'!$N:$N,'1월'!$F:$F,"C0000142",'1월'!$I:$I,D15) -> 0 | F15: =SUMIFS('1월'!$L:$L,'1월'!$F:$F,"C0000004",'1월'!$I:$I,D15)+SUMIFS('1월'!$L:$L,'1월'!$F:$F,"C0000140",'1월'!$I:$I,D15,'1월'!$T:$T,"??C*")+SUMIFS('1월'!$L:$L,'1월'!$F:$F,"C0000140",'1월'!$I:$I,D15,'1월'!$T:$T,"??M*")+SUMIFS('1월'!$L:$L,'1월'!$F:$F,"C0000140",'1월'!$I:$I,D15,'1월'!$T:$T,"??Z*")+SUMIFS('1월'!$L:$L,'1월'!$F:$F,"C0000142",'1월'!$I:$I,D15) -> 0 | G15: =IFERROR((F15/E15)-1,"") | H15: =F15+F16 -> 0 | I15: =IFERROR(DATE($B$7,I$7,$B15),"") -> 46056 | J15: =SUMIFS('2월'!$N:$N,'2월'!$F:$F,"C0000004",'2월'!$I:$I,I15)+SUMIFS('2월'!$N:$N,'2월'!$F:$F,"C0000140",'2월'!$I:$I,I15,'2월'!$T:$T,"??C*")+SUMIFS('2월'!$N:$N,'2월'!$F:$F,"C0000140",'2월'!$I:$I,I15,'2월'!$T:$T,"??M*")+SUMIFS('2월'!$N:$N,'2월'!$F:$F,"C0000140",'2월'!$I:$I,I15,'2월'!$T:$T,"??Z*")+SUMIFS('2월'!$N:$N,'2월'!$F:$F,"C0000142",'2월'!$I:$I,I15) -> 0 | K15: =SUMIFS('2월'!$L:$L,'2월'!$F:$F,"C0000004",'2월'!$I:$I,I15)+SUMIFS('2월'!$L:$L,'2월'!$F:$F,"C0000140",'2월'!$I:$I,I15,'2월'!$T:$T,"??C*")+SUMIFS('2월'!$L:$L,'2월'!$F:$F,"C0000140",'2월'!$I:$I,I15,'2월'!$T:$T,"??M*")+SUMIFS('2월'!$L:$L,'2월'!$F:$F,"C0000140",'2월'!$I:$I,I15,'2월'!$T:$T,"??Z*")+SUMIFS('2월'!$L:$L,'2월'!$F:$F,"C0000142",'2월'!$I:$I,I15) -> 0 | L15: =IFERROR((K15/J15)-1,"") | M15: =K15+K16 -> 0 | N15: =IFERROR(DATE($B$7,N$7,$B15),"") -> 46084 | O15: =SUMIFS('3월'!$N:$N,'3월'!$F:$F,"C0000004",'3월'!$I:$I,N15)+SUMIFS('3월'!$N:$N,'3월'!$F:$F,"C0000140",'3월'!$I:$I,N15,'3월'!$T:$T,"??C*")+SUMIFS('3월'!$N:$N,'3월'!$F:$F,"C0000140",'3월'!$I:$I,N15,'3월'!$T:$T,"??M*")+SUMIFS('3월'!$N:$N,'3월'!$F:$F,"C0000140",'3월'!$I:$I,N15,'3월'!$T:$T,"??Z*")+SUMIFS('3월'!$N:$N,'3월'!$F:$F,"C0000142",'3월'!$I:$I,N15) -> 0 | P15: =SUMIFS('3월'!$L:$L,'3월'!$F:$F,"C0000004",'3월'!$I:$I,N15)+SUMIFS('3월'!$L:$L,'3월'!$F:$F,"C0000140",'3월'!$I:$I,N15,'3월'!$T:$T,"??C*")+SUMIFS('3월'!$L:$L,'3월'!$F:$F,"C0000140",'3월'!$I:$I,N15,'3월'!$T:$T,"??M*")+SUMIFS('3월'!$L:$L,'3월'!$F:$F,"C0000140",'3월'!$I:$I,N15,'3월'!$T:$T,"??Z*")+SUMIFS('3월'!$L:$L,'3월'!$F:$F,"C0000142",'3월'!$I:$I,N15) -> 0 | Q15: =IFERROR((P15/O15)-1,"") | R15: =P15+P16 -> 0 | S15: =IFERROR(DATE($B$7,S$7,$B15),"") -> 46115 | T15: =SUMIFS('4월'!$N:$N,'4월'!$F:$F,"C0000004",'4월'!$I:$I,S15)+SUMIFS('4월'!$N:$N,'4월'!$F:$F,"C0000140",'4월'!$I:$I,S15,'4월'!$T:$T,"??C*")+SUMIFS('4월'!$N:$N,'4월'!$F:$F,"C0000140",'4월'!$I:$I,S15,'4월'!$T:$T,"??M*")+SUMIFS('4월'!$N:$N,'4월'!$F:$F,"C0000140",'4월'!$I:$I,S15,'4월'!$T:$T,"??Z*")+SUMIFS('4월'!$N:$N,'4월'!$F:$F,"C0000142",'4월'!$I:$I,S15) -> 0 | U15: =SUMIFS('4월'!$L:$L,'4월'!$F:$F,"C0000004",'4월'!$I:$I,S15)+SUMIFS('4월'!$L:$L,'4월'!$F:$F,"C0000140",'4월'!$I:$I,S15,'4월'!$T:$T,"??C*")+SUMIFS('4월'!$L:$L,'4월'!$F:$F,"C0000140",'4월'!$I:$I,S15,'4월'!$T:$T,"??M*")+SUMIFS('4월'!$L:$L,'4월'!$F:$F,"C0000140",'4월'!$I:$I,S15,'4월'!$T:$T,"??Z*")+SUMIFS('4월'!$L:$L,'4월'!$F:$F,"C0000142",'4월'!$I:$I,S15) -> 0 | V15: =IFERROR((U15/T15)-1,"") | W15: =U15+U16 -> 0 | X15: =IFERROR(DATE($B$7,X$7,$B15),"") -> 46145 | Y15: =SUMIFS('5월'!$N:$N,'5월'!$F:$F,"C0000004",'5월'!$I:$I,X15)+SUMIFS('5월'!$N:$N,'5월'!$F:$F,"C0000140",'5월'!$I:$I,X15,'5월'!$T:$T,"??C*")+SUMIFS('5월'!$N:$N,'5월'!$F:$F,"C0000140",'5월'!$I:$I,X15,'5월'!$T:$T,"??M*")+SUMIFS('5월'!$N:$N,'5월'!$F:$F,"C0000140",'5월'!$I:$I,X15,'5월'!$T:$T,"??Z*")+SUMIFS('5월'!$N:$N,'5월'!$F:$F,"C0000142",'5월'!$I:$I,X15) -> 0 | Z15: =SUMIFS('5월'!$L:$L,'5월'!$F:$F,"C0000004",'5월'!$I:$I,X15)+SUMIFS('5월'!$L:$L,'5월'!$F:$F,"C0000140",'5월'!$I:$I,X15,'5월'!$T:$T,"??C*")+SUMIFS('5월'!$L:$L,'5월'!$F:$F,"C0000140",'5월'!$I:$I,X15,'5월'!$T:$T,"??M*")+SUMIFS('5월'!$L:$L,'5월'!$F:$F,"C0000140",'5월'!$I:$I,X15,'5월'!$T:$T,"??Z*")+SUMIFS('5월'!$L:$L,'5월'!$F:$F,"C0000142",'5월'!$I:$I,X15) -> 0 | AA15: =IFERROR((Z15/Y15)-1,"") | AB15: =Z15+Z16 -> 0 | AC15: =IFERROR(DATE($B$7,AC$7,$B15),"") -> 46176 | AD15: =SUMIFS('6월'!$N:$N,'6월'!$F:$F,"C0000004",'6월'!$I:$I,AC15)+SUMIFS('6월'!$N:$N,'6월'!$F:$F,"C0000140",'6월'!$I:$I,AC15,'6월'!$T:$T,"??C*")+SUMIFS('6월'!$N:$N,'6월'!$F:$F,"C0000140",'6월'!$I:$I,AC15,'6월'!$T:$T,"??M*")+SUMIFS('6월'!$N:$N,'6월'!$F:$F,"C0000140",'6월'!$I:$I,AC15,'6월'!$T:$T,"??Z*")+SUMIFS('6월'!$N:$N,'6월'!$F:$F,"C0000142",'6월'!$I:$I,AC15) -> 0 | AE15: =SUMIFS('6월'!$L:$L,'6월'!$F:$F,"C0000004",'6월'!$I:$I,AC15)+SUMIFS('6월'!$L:$L,'6월'!$F:$F,"C0000140",'6월'!$I:$I,AC15,'6월'!$T:$T,"??C*")+SUMIFS('6월'!$L:$L,'6월'!$F:$F,"C0000140",'6월'!$I:$I,AC15,'6월'!$T:$T,"??M*")+SUMIFS('6월'!$L:$L,'6월'!$F:$F,"C0000140",'6월'!$I:$I,AC15,'6월'!$T:$T,"??Z*")+SUMIFS('6월'!$L:$L,'6월'!$F:$F,"C0000142",'6월'!$I:$I,AC15) -> 0 | AF15: =IFERROR((AE15/AD15)-1,"") | AG15: =AE15+AE16 -> 0 | AH15: =IFERROR(DATE($B$7,AH$7,$B15),"") -> 46206 | AI15: =SUMIFS('7월'!$N:$N,'7월'!$F:$F,"C0000004",'7월'!$I:$I,AH15)+SUMIFS('7월'!$N:$N,'7월'!$F:$F,"C0000140",'7월'!$I:$I,AH15,'7월'!$T:$T,"??C*")+SUMIFS('7월'!$N:$N,'7월'!$F:$F,"C0000140",'7월'!$I:$I,AH15,'7월'!$T:$T,"??M*")+SUMIFS('7월'!$N:$N,'7월'!$F:$F,"C0000140",'7월'!$I:$I,AH15,'7월'!$T:$T,"??Z*")+SUMIFS('7월'!$N:$N,'7월'!$F:$F,"C0000142",'7월'!$I:$I,AH15) -> 0 | AJ15: =SUMIFS('7월'!$L:$L,'7월'!$F:$F,"C0000004",'7월'!$I:$I,AH15)+SUMIFS('7월'!$L:$L,'7월'!$F:$F,"C0000140",'7월'!$I:$I,AH15,'7월'!$T:$T,"??C*")+SUMIFS('7월'!$L:$L,'7월'!$F:$F,"C0000140",'7월'!$I:$I,AH15,'7월'!$T:$T,"??M*")+SUMIFS('7월'!$L:$L,'7월'!$F:$F,"C0000140",'7월'!$I:$I,AH15,'7월'!$T:$T,"??Z*")+SUMIFS('7월'!$L:$L,'7월'!$F:$F,"C0000142",'7월'!$I:$I,AH15) -> 0 | AK15: =IFERROR((AJ15/AI15)-1,"") | AL15: =AJ15+AJ16 -> 0 | AM15: =IFERROR(DATE($B$7,AM$7,$B15),"") -> 46237 | AN15: =SUMIFS('8월'!$N:$N,'8월'!$F:$F,"C0000004",'8월'!$I:$I,AM15)+SUMIFS('8월'!$N:$N,'8월'!$F:$F,"C0000140",'8월'!$I:$I,AM15,'8월'!$T:$T,"??C*")+SUMIFS('8월'!$N:$N,'8월'!$F:$F,"C0000140",'8월'!$I:$I,AM15,'8월'!$T:$T,"??M*")+SUMIFS('8월'!$N:$N,'8월'!$F:$F,"C0000140",'8월'!$I:$I,AM15,'8월'!$T:$T,"??Z*")+SUMIFS('8월'!$N:$N,'8월'!$F:$F,"C0000142",'8월'!$I:$I,AM15) -> 0 | AO15: =SUMIFS('8월'!$L:$L,'8월'!$F:$F,"C0000004",'8월'!$I:$I,AM15)+SUMIFS('8월'!$L:$L,'8월'!$F:$F,"C0000140",'8월'!$I:$I,AM15,'8월'!$T:$T,"??C*")+SUMIFS('8월'!$L:$L,'8월'!$F:$F,"C0000140",'8월'!$I:$I,AM15,'8월'!$T:$T,"??M*")+SUMIFS('8월'!$L:$L,'8월'!$F:$F,"C0000140",'8월'!$I:$I,AM15,'8월'!$T:$T,"??Z*")+SUMIFS('8월'!$L:$L,'8월'!$F:$F,"C0000142",'8월'!$I:$I,AM15) -> 0 | AP15: =IFERROR((AO15/AN15)-1,"") | AQ15: =AO15+AO16 -> 0 | AR15: =IFERROR(DATE($B$7,AR$7,$B15),"") -> 46268 | AS15: =SUMIFS('9월'!$N:$N,'9월'!$F:$F,"C0000004",'9월'!$I:$I,AR15)+SUMIFS('9월'!$N:$N,'9월'!$F:$F,"C0000140",'9월'!$I:$I,AR15,'9월'!$T:$T,"??C*")+SUMIFS('9월'!$N:$N,'9월'!$F:$F,"C0000140",'9월'!$I:$I,AR15,'9월'!$T:$T,"??M*")+SUMIFS('9월'!$N:$N,'9월'!$F:$F,"C0000140",'9월'!$I:$I,AR15,'9월'!$T:$T,"??Z*")+SUMIFS('9월'!$N:$N,'9월'!$F:$F,"C0000142",'9월'!$I:$I,AR15) -> 24800 | AT15: =SUMIFS('9월'!$L:$L,'9월'!$F:$F,"C0000004",'9월'!$I:$I,AR15)+SUMIFS('9월'!$L:$L,'9월'!$F:$F,"C0000140",'9월'!$I:$I,AR15,'9월'!$T:$T,"??C*")+SUMIFS('9월'!$L:$L,'9월'!$F:$F,"C0000140",'9월'!$I:$I,AR15,'9월'!$T:$T,"??M*")+SUMIFS('9월'!$L:$L,'9월'!$F:$F,"C0000140",'9월'!$I:$I,AR15,'9월'!$T:$T,"??Z*")+SUMIFS('9월'!$L:$L,'9월'!$F:$F,"C0000142",'9월'!$I:$I,AR15) -> 31000 | AU15: =IFERROR((AT15/AS15)-1,"") -> 0.25 | AV15: =AT15+AT16 -> 31000 | AW15: =IFERROR(DATE($B$7,AW$7,$B15),"") -> 46298 | AX15: =SUMIFS('10월'!$N:$N,'10월'!$F:$F,"C0000004",'10월'!$I:$I,AW15)+SUMIFS('10월'!$N:$N,'10월'!$F:$F,"C0000140",'10월'!$I:$I,AW15,'10월'!$T:$T,"??C*")+SUMIFS('10월'!$N:$N,'10월'!$F:$F,"C0000140",'10월'!$I:$I,AW15,'10월'!$T:$T,"??M*")+SUMIFS('10월'!$N:$N,'10월'!$F:$F,"C0000140",'10월'!$I:$I,AW15,'10월'!$T:$T,"??Z*")+SUMIFS('10월'!$N:$N,'10월'!$F:$F,"C0000142",'10월'!$I:$I,AW15) -> 0 | AY15: =SUMIFS('10월'!$L:$L,'10월'!$F:$F,"C0000004",'10월'!$I:$I,AW15)+SUMIFS('10월'!$L:$L,'10월'!$F:$F,"C0000140",'10월'!$I:$I,AW15,'10월'!$T:$T,"??C*")+SUMIFS('10월'!$L:$L,'10월'!$F:$F,"C0000140",'10월'!$I:$I,AW15,'10월'!$T:$T,"??M*")+SUMIFS('10월'!$L:$L,'10월'!$F:$F,"C0000140",'10월'!$I:$I,AW15,'10월'!$T:$T,"??Z*")+SUMIFS('10월'!$L:$L,'10월'!$F:$F,"C0000142",'10월'!$I:$I,AW15) -> 0 | AZ15: =IFERROR((AY15/AX15)-1,"") | BA15: =AY15+AY16 -> 0 | BB15: =IFERROR(DATE($B$7,BB$7,$B15),"") -> 46329 | BC15: =SUMIFS('11월'!$N:$N,'11월'!$F:$F,"C0000004",'11월'!$I:$I,BB15)+SUMIFS('11월'!$N:$N,'11월'!$F:$F,"C0000140",'11월'!$I:$I,BB15,'11월'!$T:$T,"??C*")+SUMIFS('11월'!$N:$N,'11월'!$F:$F,"C0000140",'11월'!$I:$I,BB15,'11월'!$T:$T,"??M*")+SUMIFS('11월'!$N:$N,'11월'!$F:$F,"C0000140",'11월'!$I:$I,BB15,'11월'!$T:$T,"??Z*")+SUMIFS('11월'!$N:$N,'11월'!$F:$F,"C0000142",'11월'!$I:$I,BB15) -> 0 | BD15: =SUMIFS('11월'!$L:$L,'11월'!$F:$F,"C0000004",'11월'!$I:$I,BB15)+SUMIFS('11월'!$L:$L,'11월'!$F:$F,"C0000140",'11월'!$I:$I,BB15,'11월'!$T:$T,"??C*")+SUMIFS('11월'!$L:$L,'11월'!$F:$F,"C0000140",'11월'!$I:$I,BB15,'11월'!$T:$T,"??M*")+SUMIFS('11월'!$L:$L,'11월'!$F:$F,"C0000140",'11월'!$I:$I,BB15,'11월'!$T:$T,"??Z*")+SUMIFS('11월'!$L:$L,'11월'!$F:$F,"C0000142",'11월'!$I:$I,BB15) -> 0 | BE15: =IFERROR((BD15/BC15)-1,"") | BF15: =BD15+BD16 -> 0 | BG15: =IFERROR(DATE($B$7,BG$7,$B15),"") -> 46359 | BH15: =SUMIFS('12월'!$N:$N,'12월'!$F:$F,"C0000004",'12월'!$I:$I,BG15)+SUMIFS('12월'!$N:$N,'12월'!$F:$F,"C0000140",'12월'!$I:$I,BG15,'12월'!$T:$T,"??C*")+SUMIFS('12월'!$N:$N,'12월'!$F:$F,"C0000140",'12월'!$I:$I,BG15,'12월'!$T:$T,"??M*")+SUMIFS('12월'!$N:$N,'12월'!$F:$F,"C0000140",'12월'!$I:$I,BG15,'12월'!$T:$T,"??Z*")+SUMIFS('12월'!$N:$N,'12월'!$F:$F,"C0000142",'12월'!$I:$I,BG15) -> 0 | BI15: =SUMIFS('12월'!$L:$L,'12월'!$F:$F,"C0000004",'12월'!$I:$I,BG15)+SUMIFS('12월'!$L:$L,'12월'!$F:$F,"C0000140",'12월'!$I:$I,BG15,'12월'!$T:$T,"??C*")+SUMIFS('12월'!$L:$L,'12월'!$F:$F,"C0000140",'12월'!$I:$I,BG15,'12월'!$T:$T,"??M*")+SUMIFS('12월'!$L:$L,'12월'!$F:$F,"C0000140",'12월'!$I:$I,BG15,'12월'!$T:$T,"??Z*")+SUMIFS('12월'!$L:$L,'12월'!$F:$F,"C0000142",'12월'!$I:$I,BG15) -> 0 | BJ15: =IFERROR((BI15/BH15)-1,"") | BK15: =BI15+BI16 -> 0
C16: L | E16: =SUMIFS('1월'!$N:$N,'1월'!$F:$F,"*L*",'1월'!$I:$I,D15,'1월'!$S:$S,"윤준희") -> 0 | F16: =SUMIFS('1월'!$L:$L,'1월'!$F:$F,"*L*",'1월'!$I:$I,D15,'1월'!$S:$S,"윤준희") -> 0 | G16: =IFERROR((F16/E16)-1,"") | J16: =SUMIFS('2월'!$N:$N,'2월'!$F:$F,"*L*",'2월'!$I:$I,I15,'2월'!$S:$S,"윤준희") -> 0 | K16: =SUMIFS('2월'!$L:$L,'2월'!$F:$F,"*L*",'2월'!$I:$I,I15,'2월'!$S:$S,"윤준희") -> 0 | L16: =IFERROR((K16/J16)-1,"") | O16: =SUMIFS('3월'!$N:$N,'3월'!$F:$F,"*L*",'3월'!$I:$I,N15,'3월'!$S:$S,"윤준희") -> 0 | P16: =SUMIFS('3월'!$L:$L,'3월'!$F:$F,"*L*",'3월'!$I:$I,N15,'3월'!$S:$S,"윤준희") -> 0 | Q16: =IFERROR((P16/O16)-1,"") | T16: =SUMIFS('4월'!$N:$N,'4월'!$F:$F,"*L*",'4월'!$I:$I,S15,'4월'!$S:$S,"윤준희") -> 0 | U16: =SUMIFS('4월'!$L:$L,'4월'!$F:$F,"*L*",'4월'!$I:$I,S15,'4월'!$S:$S,"윤준희") -> 0 | V16: =IFERROR((U16/T16)-1,"") | Y16: =SUMIFS('5월'!$N:$N,'5월'!$F:$F,"*L*",'5월'!$I:$I,X15,'5월'!$S:$S,"윤준희") -> 0 | Z16: =SUMIFS('5월'!$L:$L,'5월'!$F:$F,"*L*",'5월'!$I:$I,X15,'5월'!$S:$S,"윤준희") -> 0 | AA16: =IFERROR((Z16/Y16)-1,"") | AD16: =SUMIFS('6월'!$N:$N,'6월'!$F:$F,"*L*",'6월'!$I:$I,AC15,'6월'!$S:$S,"윤준희") -> 0 | AE16: =SUMIFS('6월'!$L:$L,'6월'!$F:$F,"*L*",'6월'!$I:$I,AC15,'6월'!$S:$S,"윤준희")+SUMIFS('6월'!$L:$L,'6월'!$F:$F,"*L*",'6월'!$I:$I,AC15,'6월'!$S:$S,"윤준희") -> 0 | AF16: =IFERROR((AE16/AD16)-1,"") | AI16: =SUMIFS('7월'!$N:$N,'7월'!$F:$F,"*L*",'7월'!$I:$I,AH15,'7월'!$S:$S,"윤준희") -> 0 | AJ16: =SUMIFS('7월'!$L:$L,'7월'!$F:$F,"*L*",'7월'!$I:$I,AH15,'7월'!$S:$S,"윤준희") -> 0 | AK16: =IFERROR((AJ16/AI16)-1,"") | AN16: =SUMIFS('8월'!$N:$N,'8월'!$F:$F,"*L*",'8월'!$I:$I,AM15,'8월'!$S:$S,"윤준희") -> 0 | AO16: =SUMIFS('8월'!$L:$L,'8월'!$F:$F,"*L*",'8월'!$I:$I,AM15,'8월'!$S:$S,"윤준희") -> 0 | AP16: =IFERROR((AO16/AN16)-1,"") | AS16: =SUMIFS('9월'!$N:$N,'9월'!$F:$F,"*L*",'9월'!$I:$I,AR15,'9월'!$S:$S,"윤준희") -> 0 | AT16: =SUMIFS('9월'!$L:$L,'9월'!$F:$F,"*L*",'9월'!$I:$I,AR15,'9월'!$S:$S,"윤준희") -> 0 | AU16: =IFERROR((AT16/AS16)-1,"") | AX16: =SUMIFS('10월'!$N:$N,'10월'!$F:$F,"*L*",'10월'!$I:$I,AW15,'10월'!$S:$S,"윤준희") -> 0 | AY16: =SUMIFS('10월'!$L:$L,'10월'!$F:$F,"*L*",'10월'!$I:$I,AW15,'10월'!$S:$S,"윤준희") -> 0 | AZ16: =IFERROR((AY16/AX16)-1,"") | BC16: =SUMIFS('11월'!$N:$N,'11월'!$F:$F,"*L*",'11월'!$I:$I,BB15,'11월'!$S:$S,"윤준희") -> 0 | BD16: =SUMIFS('11월'!$L:$L,'11월'!$F:$F,"*L*",'11월'!$I:$I,BB15,'11월'!$S:$S,"윤준희") -> 0 | BE16: =IFERROR((BD16/BC16)-1,"") | BH16: =SUMIFS('12월'!$N:$N,'12월'!$F:$F,"*L*",'12월'!$I:$I,BG15,'12월'!$S:$S,"윤준희") -> 0 | BI16: =SUMIFS('12월'!$L:$L,'12월'!$F:$F,"*L*",'12월'!$I:$I,BG15,'12월'!$S:$S,"윤준희") -> 0 | BJ16: =IFERROR((BI16/BH16)-1,"")
B17: 4 | C17: C | D17: =IFERROR(DATE($B$7,$D$7,B17),"") -> 46026 | E17: =SUMIFS('1월'!$N:$N,'1월'!$F:$F,"C0000004",'1월'!$I:$I,D17)+SUMIFS('1월'!$N:$N,'1월'!$F:$F,"C0000140",'1월'!$I:$I,D17,'1월'!$T:$T,"??C*")+SUMIFS('1월'!$N:$N,'1월'!$F:$F,"C0000140",'1월'!$I:$I,D17,'1월'!$T:$T,"??M*")+SUMIFS('1월'!$N:$N,'1월'!$F:$F,"C0000140",'1월'!$I:$I,D17,'1월'!$T:$T,"??Z*")+SUMIFS('1월'!$N:$N,'1월'!$F:$F,"C0000142",'1월'!$I:$I,D17) -> 0 | F17: =SUMIFS('1월'!$L:$L,'1월'!$F:$F,"C0000004",'1월'!$I:$I,D17)+SUMIFS('1월'!$L:$L,'1월'!$F:$F,"C0000140",'1월'!$I:$I,D17,'1월'!$T:$T,"??C*")+SUMIFS('1월'!$L:$L,'1월'!$F:$F,"C0000140",'1월'!$I:$I,D17,'1월'!$T:$T,"??M*")+SUMIFS('1월'!$L:$L,'1월'!$F:$F,"C0000140",'1월'!$I:$I,D17,'1월'!$T:$T,"??Z*")+SUMIFS('1월'!$L:$L,'1월'!$F:$F,"C0000142",'1월'!$I:$I,D17) -> 0 | G17: =IFERROR((F17/E17)-1,"") | H17: =F17+F18 -> 0 | I17: =IFERROR(DATE($B$7,I$7,$B17),"") -> 46057 | J17: =SUMIFS('2월'!$N:$N,'2월'!$F:$F,"C0000004",'2월'!$I:$I,I17)+SUMIFS('2월'!$N:$N,'2월'!$F:$F,"C0000140",'2월'!$I:$I,I17,'2월'!$T:$T,"??C*")+SUMIFS('2월'!$N:$N,'2월'!$F:$F,"C0000140",'2월'!$I:$I,I17,'2월'!$T:$T,"??M*")+SUMIFS('2월'!$N:$N,'2월'!$F:$F,"C0000140",'2월'!$I:$I,I17,'2월'!$T:$T,"??Z*")+SUMIFS('2월'!$N:$N,'2월'!$F:$F,"C0000142",'2월'!$I:$I,I17) -> 0 | K17: =SUMIFS('2월'!$L:$L,'2월'!$F:$F,"C0000004",'2월'!$I:$I,I17)+SUMIFS('2월'!$L:$L,'2월'!$F:$F,"C0000140",'2월'!$I:$I,I17,'2월'!$T:$T,"??C*")+SUMIFS('2월'!$L:$L,'2월'!$F:$F,"C0000140",'2월'!$I:$I,I17,'2월'!$T:$T,"??M*")+SUMIFS('2월'!$L:$L,'2월'!$F:$F,"C0000140",'2월'!$I:$I,I17,'2월'!$T:$T,"??Z*")+SUMIFS('2월'!$L:$L,'2월'!$F:$F,"C0000142",'2월'!$I:$I,I17) -> 0 | L17: =IFERROR((K17/J17)-1,"") | M17: =K17+K18 -> 0 | N17: =IFERROR(DATE($B$7,N$7,$B17),"") -> 46085 | O17: =SUMIFS('3월'!$N:$N,'3월'!$F:$F,"C0000004",'3월'!$I:$I,N17)+SUMIFS('3월'!$N:$N,'3월'!$F:$F,"C0000140",'3월'!$I:$I,N17,'3월'!$T:$T,"??C*")+SUMIFS('3월'!$N:$N,'3월'!$F:$F,"C0000140",'3월'!$I:$I,N17,'3월'!$T:$T,"??M*")+SUMIFS('3월'!$N:$N,'3월'!$F:$F,"C0000140",'3월'!$I:$I,N17,'3월'!$T:$T,"??Z*")+SUMIFS('3월'!$N:$N,'3월'!$F:$F,"C0000142",'3월'!$I:$I,N17) -> 0 | P17: =SUMIFS('3월'!$L:$L,'3월'!$F:$F,"C0000004",'3월'!$I:$I,N17)+SUMIFS('3월'!$L:$L,'3월'!$F:$F,"C0000140",'3월'!$I:$I,N17,'3월'!$T:$T,"??C*")+SUMIFS('3월'!$L:$L,'3월'!$F:$F,"C0000140",'3월'!$I:$I,N17,'3월'!$T:$T,"??M*")+SUMIFS('3월'!$L:$L,'3월'!$F:$F,"C0000140",'3월'!$I:$I,N17,'3월'!$T:$T,"??Z*")+SUMIFS('3월'!$L:$L,'3월'!$F:$F,"C0000142",'3월'!$I:$I,N17) -> 0 | Q17: =IFERROR((P17/O17)-1,"") | R17: =P17+P18 -> 0 | S17: =IFERROR(DATE($B$7,S$7,$B17),"") -> 46116 | T17: =SUMIFS('4월'!$N:$N,'4월'!$F:$F,"C0000004",'4월'!$I:$I,S17)+SUMIFS('4월'!$N:$N,'4월'!$F:$F,"C0000140",'4월'!$I:$I,S17,'4월'!$T:$T,"??C*")+SUMIFS('4월'!$N:$N,'4월'!$F:$F,"C0000140",'4월'!$I:$I,S17,'4월'!$T:$T,"??M*")+SUMIFS('4월'!$N:$N,'4월'!$F:$F,"C0000140",'4월'!$I:$I,S17,'4월'!$T:$T,"??Z*")+SUMIFS('4월'!$N:$N,'4월'!$F:$F,"C0000142",'4월'!$I:$I,S17) -> 0 | U17: =SUMIFS('4월'!$L:$L,'4월'!$F:$F,"C0000004",'4월'!$I:$I,S17)+SUMIFS('4월'!$L:$L,'4월'!$F:$F,"C0000140",'4월'!$I:$I,S17,'4월'!$T:$T,"??C*")+SUMIFS('4월'!$L:$L,'4월'!$F:$F,"C0000140",'4월'!$I:$I,S17,'4월'!$T:$T,"??M*")+SUMIFS('4월'!$L:$L,'4월'!$F:$F,"C0000140",'4월'!$I:$I,S17,'4월'!$T:$T,"??Z*")+SUMIFS('4월'!$L:$L,'4월'!$F:$F,"C0000142",'4월'!$I:$I,S17) -> 0 | V17: =IFERROR((U17/T17)-1,"") | W17: =U17+U18 -> 0 | X17: =IFERROR(DATE($B$7,X$7,$B17),"") -> 46146 | Y17: =SUMIFS('5월'!$N:$N,'5월'!$F:$F,"C0000004",'5월'!$I:$I,X17)+SUMIFS('5월'!$N:$N,'5월'!$F:$F,"C0000140",'5월'!$I:$I,X17,'5월'!$T:$T,"??C*")+SUMIFS('5월'!$N:$N,'5월'!$F:$F,"C0000140",'5월'!$I:$I,X17,'5월'!$T:$T,"??M*")+SUMIFS('5월'!$N:$N,'5월'!$F:$F,"C0000140",'5월'!$I:$I,X17,'5월'!$T:$T,"??Z*")+SUMIFS('5월'!$N:$N,'5월'!$F:$F,"C0000142",'5월'!$I:$I,X17) -> 0 | Z17: =SUMIFS('5월'!$L:$L,'5월'!$F:$F,"C0000004",'5월'!$I:$I,X17)+SUMIFS('5월'!$L:$L,'5월'!$F:$F,"C0000140",'5월'!$I:$I,X17,'5월'!$T:$T,"??C*")+SUMIFS('5월'!$L:$L,'5월'!$F:$F,"C0000140",'5월'!$I:$I,X17,'5월'!$T:$T,"??M*")+SUMIFS('5월'!$L:$L,'5월'!$F:$F,"C0000140",'5월'!$I:$I,X17,'5월'!$T:$T,"??Z*")+SUMIFS('5월'!$L:$L,'5월'!$F:$F,"C0000142",'5월'!$I:$I,X17) -> 0 | AA17: =IFERROR((Z17/Y17)-1,"") | AB17: =Z17+Z18 -> 0 | AC17: =IFERROR(DATE($B$7,AC$7,$B17),"") -> 46177 | AD17: =SUMIFS('6월'!$N:$N,'6월'!$F:$F,"C0000004",'6월'!$I:$I,AC17)+SUMIFS('6월'!$N:$N,'6월'!$F:$F,"C0000140",'6월'!$I:$I,AC17,'6월'!$T:$T,"??C*")+SUMIFS('6월'!$N:$N,'6월'!$F:$F,"C0000140",'6월'!$I:$I,AC17,'6월'!$T:$T,"??M*")+SUMIFS('6월'!$N:$N,'6월'!$F:$F,"C0000140",'6월'!$I:$I,AC17,'6월'!$T:$T,"??Z*")+SUMIFS('6월'!$N:$N,'6월'!$F:$F,"C0000142",'6월'!$I:$I,AC17) -> 0 | AE17: =SUMIFS('6월'!$L:$L,'6월'!$F:$F,"C0000004",'6월'!$I:$I,AC17)+SUMIFS('6월'!$L:$L,'6월'!$F:$F,"C0000140",'6월'!$I:$I,AC17,'6월'!$T:$T,"??C*")+SUMIFS('6월'!$L:$L,'6월'!$F:$F,"C0000140",'6월'!$I:$I,AC17,'6월'!$T:$T,"??M*")+SUMIFS('6월'!$L:$L,'6월'!$F:$F,"C0000140",'6월'!$I:$I,AC17,'6월'!$T:$T,"??Z*")+SUMIFS('6월'!$L:$L,'6월'!$F:$F,"C0000142",'6월'!$I:$I,AC17) -> 0 | AF17: =IFERROR((AE17/AD17)-1,"") | AG17: =AE17+AE18 -> 0 | AH17: =IFERROR(DATE($B$7,AH$7,$B17),"") -> 46207 | AI17: =SUMIFS('7월'!$N:$N,'7월'!$F:$F,"C0000004",'7월'!$I:$I,AH17)+SUMIFS('7월'!$N:$N,'7월'!$F:$F,"C0000140",'7월'!$I:$I,AH17,'7월'!$T:$T,"??C*")+SUMIFS('7월'!$N:$N,'7월'!$F:$F,"C0000140",'7월'!$I:$I,AH17,'7월'!$T:$T,"??M*")+SUMIFS('7월'!$N:$N,'7월'!$F:$F,"C0000140",'7월'!$I:$I,AH17,'7월'!$T:$T,"??Z*")+SUMIFS('7월'!$N:$N,'7월'!$F:$F,"C0000142",'7월'!$I:$I,AH17) -> 0 | AJ17: =SUMIFS('7월'!$L:$L,'7월'!$F:$F,"C0000004",'7월'!$I:$I,AH17)+SUMIFS('7월'!$L:$L,'7월'!$F:$F,"C0000140",'7월'!$I:$I,AH17,'7월'!$T:$T,"??C*")+SUMIFS('7월'!$L:$L,'7월'!$F:$F,"C0000140",'7월'!$I:$I,AH17,'7월'!$T:$T,"??M*")+SUMIFS('7월'!$L:$L,'7월'!$F:$F,"C0000140",'7월'!$I:$I,AH17,'7월'!$T:$T,"??Z*")+SUMIFS('7월'!$L:$L,'7월'!$F:$F,"C0000142",'7월'!$I:$I,AH17) -> 0 | AK17: =IFERROR((AJ17/AI17)-1,"") | AL17: =AJ17+AJ18 -> 0 | AM17: =IFERROR(DATE($B$7,AM$7,$B17),"") -> 46238 | AN17: =SUMIFS('8월'!$N:$N,'8월'!$F:$F,"C0000004",'8월'!$I:$I,AM17)+SUMIFS('8월'!$N:$N,'8월'!$F:$F,"C0000140",'8월'!$I:$I,AM17,'8월'!$T:$T,"??C*")+SUMIFS('8월'!$N:$N,'8월'!$F:$F,"C0000140",'8월'!$I:$I,AM17,'8월'!$T:$T,"??M*")+SUMIFS('8월'!$N:$N,'8월'!$F:$F,"C0000140",'8월'!$I:$I,AM17,'8월'!$T:$T,"??Z*")+SUMIFS('8월'!$N:$N,'8월'!$F:$F,"C0000142",'8월'!$I:$I,AM17) -> 0 | AO17: =SUMIFS('8월'!$L:$L,'8월'!$F:$F,"C0000004",'8월'!$I:$I,AM17)+SUMIFS('8월'!$L:$L,'8월'!$F:$F,"C0000140",'8월'!$I:$I,AM17,'8월'!$T:$T,"??C*")+SUMIFS('8월'!$L:$L,'8월'!$F:$F,"C0000140",'8월'!$I:$I,AM17,'8월'!$T:$T,"??M*")+SUMIFS('8월'!$L:$L,'8월'!$F:$F,"C0000140",'8월'!$I:$I,AM17,'8월'!$T:$T,"??Z*")+SUMIFS('8월'!$L:$L,'8월'!$F:$F,"C0000142",'8월'!$I:$I,AM17) -> 0 | AP17: =IFERROR((AO17/AN17)-1,"") | AQ17: =AO17+AO18 -> 0 | AR17: =IFERROR(DATE($B$7,AR$7,$B17),"") -> 46269 | AS17: =SUMIFS('9월'!$N:$N,'9월'!$F:$F,"C0000004",'9월'!$I:$I,AR17)+SUMIFS('9월'!$N:$N,'9월'!$F:$F,"C0000140",'9월'!$I:$I,AR17,'9월'!$T:$T,"??C*")+SUMIFS('9월'!$N:$N,'9월'!$F:$F,"C0000140",'9월'!$I:$I,AR17,'9월'!$T:$T,"??M*")+SUMIFS('9월'!$N:$N,'9월'!$F:$F,"C0000140",'9월'!$I:$I,AR17,'9월'!$T:$T,"??Z*")+SUMIFS('9월'!$N:$N,'9월'!$F:$F,"C0000142",'9월'!$I:$I,AR17) -> 885870 | AT17: =SUMIFS('9월'!$L:$L,'9월'!$F:$F,"C0000004",'9월'!$I:$I,AR17)+SUMIFS('9월'!$L:$L,'9월'!$F:$F,"C0000140",'9월'!$I:$I,AR17,'9월'!$T:$T,"??C*")+SUMIFS('9월'!$L:$L,'9월'!$F:$F,"C0000140",'9월'!$I:$I,AR17,'9월'!$T:$T,"??M*")+SUMIFS('9월'!$L:$L,'9월'!$F:$F,"C0000140",'9월'!$I:$I,AR17,'9월'!$T:$T,"??Z*")+SUMIFS('9월'!$L:$L,'9월'!$F:$F,"C0000142",'9월'!$I:$I,AR17) -> 1020600 | AU17: =IFERROR((AT17/AS17)-1,"") -> 0.15208778 | AV17: =AT17+AT18 -> 1020600 | AW17: =IFERROR(DATE($B$7,AW$7,$B17),"") -> 46299 | AX17: =SUMIFS('10월'!$N:$N,'10월'!$F:$F,"C0000004",'10월'!$I:$I,AW17)+SUMIFS('10월'!$N:$N,'10월'!$F:$F,"C0000140",'10월'!$I:$I,AW17,'10월'!$T:$T,"??C*")+SUMIFS('10월'!$N:$N,'10월'!$F:$F,"C0000140",'10월'!$I:$I,AW17,'10월'!$T:$T,"??M*")+SUMIFS('10월'!$N:$N,'10월'!$F:$F,"C0000140",'10월'!$I:$I,AW17,'10월'!$T:$T,"??Z*")+SUMIFS('10월'!$N:$N,'10월'!$F:$F,"C0000142",'10월'!$I:$I,AW17) -> 0 | AY17: =SUMIFS('10월'!$L:$L,'10월'!$F:$F,"C0000004",'10월'!$I:$I,AW17)+SUMIFS('10월'!$L:$L,'10월'!$F:$F,"C0000140",'10월'!$I:$I,AW17,'10월'!$T:$T,"??C*")+SUMIFS('10월'!$L:$L,'10월'!$F:$F,"C0000140",'10월'!$I:$I,AW17,'10월'!$T:$T,"??M*")+SUMIFS('10월'!$L:$L,'10월'!$F:$F,"C0000140",'10월'!$I:$I,AW17,'10월'!$T:$T,"??Z*")+SUMIFS('10월'!$L:$L,'10월'!$F:$F,"C0000142",'10월'!$I:$I,AW17) -> 0 | AZ17: =IFERROR((AY17/AX17)-1,"") | BA17: =AY17+AY18 -> 0 | BB17: =IFERROR(DATE($B$7,BB$7,$B17),"") -> 46330 | BC17: =SUMIFS('11월'!$N:$N,'11월'!$F:$F,"C0000004",'11월'!$I:$I,BB17)+SUMIFS('11월'!$N:$N,'11월'!$F:$F,"C0000140",'11월'!$I:$I,BB17,'11월'!$T:$T,"??C*")+SUMIFS('11월'!$N:$N,'11월'!$F:$F,"C0000140",'11월'!$I:$I,BB17,'11월'!$T:$T,"??M*")+SUMIFS('11월'!$N:$N,'11월'!$F:$F,"C0000140",'11월'!$I:$I,BB17,'11월'!$T:$T,"??Z*")+SUMIFS('11월'!$N:$N,'11월'!$F:$F,"C0000142",'11월'!$I:$I,BB17) -> 0 | BD17: =SUMIFS('11월'!$L:$L,'11월'!$F:$F,"C0000004",'11월'!$I:$I,BB17)+SUMIFS('11월'!$L:$L,'11월'!$F:$F,"C0000140",'11월'!$I:$I,BB17,'11월'!$T:$T,"??C*")+SUMIFS('11월'!$L:$L,'11월'!$F:$F,"C0000140",'11월'!$I:$I,BB17,'11월'!$T:$T,"??M*")+SUMIFS('11월'!$L:$L,'11월'!$F:$F,"C0000140",'11월'!$I:$I,BB17,'11월'!$T:$T,"??Z*")+SUMIFS('11월'!$L:$L,'11월'!$F:$F,"C0000142",'11월'!$I:$I,BB17) -> 0 | BE17: =IFERROR((BD17/BC17)-1,"") | BF17: =BD17+BD18 -> 0 | BG17: =IFERROR(DATE($B$7,BG$7,$B17),"") -> 46360 | BH17: =SUMIFS('12월'!$N:$N,'12월'!$F:$F,"C0000004",'12월'!$I:$I,BG17)+SUMIFS('12월'!$N:$N,'12월'!$F:$F,"C0000140",'12월'!$I:$I,BG17,'12월'!$T:$T,"??C*")+SUMIFS('12월'!$N:$N,'12월'!$F:$F,"C0000140",'12월'!$I:$I,BG17,'12월'!$T:$T,"??M*")+SUMIFS('12월'!$N:$N,'12월'!$F:$F,"C0000140",'12월'!$I:$I,BG17,'12월'!$T:$T,"??Z*")+SUMIFS('12월'!$N:$N,'12월'!$F:$F,"C0000142",'12월'!$I:$I,BG17) -> 0 | BI17: =SUMIFS('12월'!$L:$L,'12월'!$F:$F,"C0000004",'12월'!$I:$I,BG17)+SUMIFS('12월'!$L:$L,'12월'!$F:$F,"C0000140",'12월'!$I:$I,BG17,'12월'!$T:$T,"??C*")+SUMIFS('12월'!$L:$L,'12월'!$F:$F,"C0000140",'12월'!$I:$I,BG17,'12월'!$T:$T,"??M*")+SUMIFS('12월'!$L:$L,'12월'!$F:$F,"C0000140",'12월'!$I:$I,BG17,'12월'!$T:$T,"??Z*")+SUMIFS('12월'!$L:$L,'12월'!$F:$F,"C0000142",'12월'!$I:$I,BG17) -> 0 | BJ17: =IFERROR((BI17/BH17)-1,"") | BK17: =BI17+BI18 -> 0
C18: L | E18: =SUMIFS('1월'!$N:$N,'1월'!$F:$F,"*L*",'1월'!$I:$I,D17,'1월'!$S:$S,"윤준희") -> 0 | F18: =SUMIFS('1월'!$L:$L,'1월'!$F:$F,"*L*",'1월'!$I:$I,D17,'1월'!$S:$S,"윤준희") -> 0 | G18: =IFERROR((F18/E18)-1,"") | J18: =SUMIFS('2월'!$N:$N,'2월'!$F:$F,"*L*",'2월'!$I:$I,I17,'2월'!$S:$S,"윤준희") -> 0 | K18: =SUMIFS('2월'!$L:$L,'2월'!$F:$F,"*L*",'2월'!$I:$I,I17,'2월'!$S:$S,"윤준희") -> 0 | L18: =IFERROR((K18/J18)-1,"") | O18: =SUMIFS('3월'!$N:$N,'3월'!$F:$F,"*L*",'3월'!$I:$I,N17,'3월'!$S:$S,"윤준희") -> 0 | P18: =SUMIFS('3월'!$L:$L,'3월'!$F:$F,"*L*",'3월'!$I:$I,N17,'3월'!$S:$S,"윤준희") -> 0 | Q18: =IFERROR((P18/O18)-1,"") | T18: =SUMIFS('4월'!$N:$N,'4월'!$F:$F,"*L*",'4월'!$I:$I,S17,'4월'!$S:$S,"윤준희") -> 0 | U18: =SUMIFS('4월'!$L:$L,'4월'!$F:$F,"*L*",'4월'!$I:$I,S17,'4월'!$S:$S,"윤준희") -> 0 | V18: =IFERROR((U18/T18)-1,"") | Y18: =SUMIFS('5월'!$N:$N,'5월'!$F:$F,"*L*",'5월'!$I:$I,X17,'5월'!$S:$S,"윤준희") -> 0 | Z18: =SUMIFS('5월'!$L:$L,'5월'!$F:$F,"*L*",'5월'!$I:$I,X17,'5월'!$S:$S,"윤준희") -> 0 | AA18: =IFERROR((Z18/Y18)-1,"") | AD18: =SUMIFS('6월'!$N:$N,'6월'!$F:$F,"*L*",'6월'!$I:$I,AC17,'6월'!$S:$S,"윤준희") -> 0 | AE18: =SUMIFS('6월'!$L:$L,'6월'!$F:$F,"*L*",'6월'!$I:$I,AC17,'6월'!$S:$S,"윤준희")+SUMIFS('6월'!$L:$L,'6월'!$F:$F,"*L*",'6월'!$I:$I,AC17,'6월'!$S:$S,"윤준희") -> 0 | AF18: =IFERROR((AE18/AD18)-1,"") | AI18: =SUMIFS('7월'!$N:$N,'7월'!$F:$F,"*L*",'7월'!$I:$I,AH17,'7월'!$S:$S,"윤준희") -> 0 | AJ18: =SUMIFS('7월'!$L:$L,'7월'!$F:$F,"*L*",'7월'!$I:$I,AH17,'7월'!$S:$S,"윤준희") -> 0 | AK18: =IFERROR((AJ18/AI18)-1,"") | AN18: =SUMIFS('8월'!$N:$N,'8월'!$F:$F,"*L*",'8월'!$I:$I,AM17,'8월'!$S:$S,"윤준희") -> 0 | AO18: =SUMIFS('8월'!$L:$L,'8월'!$F:$F,"*L*",'8월'!$I:$I,AM17,'8월'!$S:$S,"윤준희") -> 0 | AP18: =IFERROR((AO18/AN18)-1,"") | AS18: =SUMIFS('9월'!$N:$N,'9월'!$F:$F,"*L*",'9월'!$I:$I,AR17,'9월'!$S:$S,"윤준희") -> 0 | AT18: =SUMIFS('9월'!$L:$L,'9월'!$F:$F,"*L*",'9월'!$I:$I,AR17,'9월'!$S:$S,"윤준희") -> 0 | AU18: =IFERROR((AT18/AS18)-1,"") | AX18: =SUMIFS('10월'!$N:$N,'10월'!$F:$F,"*L*",'10월'!$I:$I,AW17,'10월'!$S:$S,"윤준희") -> 0 | AY18: =SUMIFS('10월'!$L:$L,'10월'!$F:$F,"*L*",'10월'!$I:$I,AW17,'10월'!$S:$S,"윤준희") -> 0 | AZ18: =IFERROR((AY18/AX18)-1,"") | BC18: =SUMIFS('11월'!$N:$N,'11월'!$F:$F,"*L*",'11월'!$I:$I,BB17,'11월'!$S:$S,"윤준희") -> 0 | BD18: =SUMIFS('11월'!$L:$L,'11월'!$F:$F,"*L*",'11월'!$I:$I,BB17,'11월'!$S:$S,"윤준희") -> 0 | BE18: =IFERROR((BD18/BC18)-1,"") | BH18: =SUMIFS('12월'!$N:$N,'12월'!$F:$F,"*L*",'12월'!$I:$I,BG17,'12월'!$S:$S,"윤준희") -> 0 | BI18: =SUMIFS('12월'!$L:$L,'12월'!$F:$F,"*L*",'12월'!$I:$I,BG17,'12월'!$S:$S,"윤준희") -> 0 | BJ18: =IFERROR((BI18/BH18)-1,"")
